Workbook

Sheet Sheet3
C4: 약관 | M4: 종목 | N4: 거래유형 | O4: 적용 환율 | P4: 수량 | Q4: 매수금액 | R4: 매수일자 | S4: 비고 | T4: 매도금액 | U4: 매도일자
M5: 솔트룩스 | N5: 토스 | O5: 1 | P5: 100 | Q5: 56500 | R5: 45817 | S5: 약관 | V5: =P5*Q5 -> 5650000
D6: 매수총액 | E6: 매도총액 | F6: 잔액 | G6: 45000000 | I6: 상환일자 | J6: 원금 금액 | M6: 솔트룩스 | N6: 토스 | O6: 1 | P6: 20 | Q6: 56100 | R6: 45817 | S6: 약관 | V6: =P6*Q6 -> 1122000
C7: 45807 | D7: =SUMIF($R$5:$R$269,$C7,$V$5:$V$269) -> 24867800 | E7: =SUMIF($U$5:$U$269,$C7,$V$5:$V$269) -> 0 | F7: =D7-E7 -> 24867800 | G7: =G6-H7 -> 44620000 | H7: =SUMIF($I$7:$I$49,$C7,$J$7:$J$49) -> 380000 | I7: 45807 | J7: 200000 | M7: 솔트룩스 | N7: 토스 | O7: 1 | P7: 17 | Q7: 52900 | R7: 45818 | S7: 약관 | V7: =P7*Q7 -> 899300
C8: 45808 | D8: =SUMIF($R$5:$R$269,$C8,$V$5:$V$269) -> 0 | E8: =SUMIF($U$5:$U$269,$C8,$V$5:$V$269) -> 0 | F8: =F7+D8-E8 -> 24867800 | G8: =G7-H8 -> 44620000 | H8: =SUMIF($I$7:$I$49,$C8,$J$7:$J$49) -> 0 | I8: 45807 | J8: 180000 | M8: 코나아이 | N8: 토스 | O8: 1 | P8: 10 | Q8: 70500 | R8: 45818 | S8: 약관 | T8: 80500 | U8: 45826 | V8: =P8*Q8 -> 705000
C9: 45809 | D9: =SUMIF($R$5:$R$269,$C9,$V$5:$V$269) -> 0 | E9: =SUMIF($U$5:$U$269,$C9,$V$5:$V$269) -> 0 | F9: =F8+D9-E9 -> 24867800 | G9: =G8-H9 -> 44620000 | H9: =SUMIF($I$7:$I$49,$C9,$J$7:$J$49) -> 0 | I9: 45810 | J9: 1460000 | M9: 솔트룩스 | N9: 토스 | O9: 1 | P9: 30 | Q9: 55300 | R9: 45819 | S9: 약관 | V9: =P9*Q9 -> 1659000
C10: 45810 | D10: =SUMIF($R$5:$R$269,$C10,$V$5:$V$269) -> 7909180 | E10: =SUMIF($U$5:$U$269,$C10,$V$5:$V$269) -> 15870500 | F10: =F9+D10-E10 -> 16906480 | G10: =G9-H10 -> 43160000 | H10: =SUMIF($I$7:$I$49,$C10,$J$7:$J$49) -> 1460000 | I10: 45812 | J10: 220000 | M10: 코나아이 | N10: 토스 | O10: 1 | P10: 10 | Q10: 71100 | R10: 45819 | S10: 약관 | T10: 80500 | U10: 45826 | V10: =P10*Q10 -> 711000
C11: 45811 | D11: =SUMIF($R$5:$R$269,$C11,$V$5:$V$269) -> 0 | E11: =SUMIF($U$5:$U$269,$C11,$V$5:$V$269) -> 0 | F11: =F10+D11-E11 -> 16906480 | G11: =G10-H11 -> 43160000 | H11: =SUMIF($I$7:$I$49,$C11,$J$7:$J$49) -> 0 | I11: 45813 | J11: 170000 | M11: 코나아이 | N11: 토스 | O11: 1 | P11: 13 | Q11: 71300 | R11: 45819 | S11: 약관 | T11: 80500 | U11: 45826 | V11: =P11*Q11 -> 926900
C12: 45812 | D12: =SUMIF($R$5:$R$269,$C12,$V$5:$V$269) -> 13408600 | E12: =SUMIF($U$5:$U$269,$C12,$V$5:$V$269) -> 9754300 | F12: =F11+D12-E12 -> 20560780 | G12: =G11-H12 -> 42940000 | H12: =SUMIF($I$7:$I$49,$C12,$J$7:$J$49) -> 220000 | I12: 45817 | J12: 270000 | M12: 솔트룩스 | N12: 토스 | O12: 1 | P12: 10 | Q12: 52700 | R12: 45820 | S12: 약관 | V12: =P12*Q12 -> 527000
C13: 45813 | D13: =SUMIF($R$5:$R$269,$C13,$V$5:$V$269) -> 19892150 | E13: =SUMIF($U$5:$U$269,$C13,$V$5:$V$269) -> 4536300 | F13: =F12+D13-E13 -> 35916630 | G13: =G12-H13 -> 42770000 | H13: =SUMIF($I$7:$I$49,$C13,$J$7:$J$49) -> 170000 | I13: 45818 | J13: 900000 | M13: 솔트룩스 | N13: 토스 | O13: 1 | P13: 6 | Q13: 51000 | R13: 45820 | S13: 약관 | V13: =P13*Q13 -> 306000
C14: 45814 | D14: =SUMIF($R$5:$R$269,$C14,$V$5:$V$269) -> 0 | E14: =SUMIF($U$5:$U$269,$C14,$V$5:$V$269) -> 0 | F14: =F13+D14-E14 -> 35916630 | G14: =G13-H14 -> 42770000 | H14: =SUMIF($I$7:$I$49,$C14,$J$7:$J$49) -> 0 | I14: 45819 | J14: 300000 | M14: 신테카바이오 | N14: 토스 | O14: 1 | P14: 300 | Q14: 7940 | R14: 45820 | S14: 약관 | V14: =P14*Q14 -> 2382000
C15: 45815 | D15: =SUMIF($R$5:$R$269,$C15,$V$5:$V$269) -> 0 | E15: =SUMIF($U$5:$U$269,$C15,$V$5:$V$269) -> 0 | F15: =F14+D15-E15 -> 35916630 | G15: =G14-H15 -> 42770000 | H15: =SUMIF($I$7:$I$49,$C15,$J$7:$J$49) -> 0 | I15: 45820 | J15: 410000 | M15: 코나아이 | N15: 토스 | O15: 1 | P15: 10 | Q15: 69300 | R15: 45820 | S15: 약관 | T15: 80500 | U15: 45826 | V15: =P15*Q15 -> 693000
C16: 45816 | D16: =SUMIF($R$5:$R$269,$C16,$V$5:$V$269) -> 0 | E16: =SUMIF($U$5:$U$269,$C16,$V$5:$V$269) -> 0 | F16: =F15+D16-E16 -> 35916630 | G16: =G15-H16 -> 42770000 | H16: =SUMIF($I$7:$I$49,$C16,$J$7:$J$49) -> 0 | I16: 45824 | J16: 450000 | M16: 코나아이 | N16: 토스 | O16: 1 | P16: 9 | Q16: 69400 | R16: 45820 | S16: 약관 | T16: 80500 | U16: 45826 | V16: =P16*Q16 -> 624600
C17: 45817 | D17: =SUMIF($R$5:$R$269,$C17,$V$5:$V$269) -> 30274000 | E17: =SUMIF($U$5:$U$269,$C17,$V$5:$V$269) -> 23034500 | F17: =F16+D17-E17 -> 43156130 | G17: =G16-H17 -> 42500000 | H17: =SUMIF($I$7:$I$49,$C17,$J$7:$J$49) -> 270000 | I17: 45826 | J17: 800000
C18: 45818 | D18: =SUMIF($R$5:$R$269,$C18,$V$5:$V$269) -> 7966300 | E18: =SUMIF($U$5:$U$269,$C18,$V$5:$V$269) -> 18068450 | F18: =F17+D18-E18 -> 33053980 | G18: =G17-H18 -> 41600000 | H18: =SUMIF($I$7:$I$49,$C18,$J$7:$J$49) -> 900000 | I18: 45832 | J18: 200000
C19: 45819 | D19: =SUMIF($R$5:$R$269,$C19,$V$5:$V$269) -> 16033900 | E19: =SUMIF($U$5:$U$269,$C19,$V$5:$V$269) -> 12183000 | F19: =F18+D19-E19 -> 36904880 | G19: =G18-H19 -> 41300000 | H19: =SUMIF($I$7:$I$49,$C19,$J$7:$J$49) -> 300000 | I19: 45834 | J19: 440000 | M19: LG씨엔에스 | N19: 토스 | O19: 1 | P19: 3 | Q19: 66000 | R19: 45824 | S19: 약관 | V19: =P19*Q19 -> 198000
C20: 45820 | D20: =SUMIF($R$5:$R$269,$C20,$V$5:$V$269) -> 6858600 | E20: =SUMIF($U$5:$U$269,$C20,$V$5:$V$269) -> 10424280 | F20: =F19+D20-E20 -> 33339200 | G20: =G19-H20 -> 40890000 | H20: =SUMIF($I$7:$I$49,$C20,$J$7:$J$49) -> 410000 | I20: 45838 | J20: 750000 | M20: 신테카바이오 | N20: 토스 | O20: 1 | P20: 65 | Q20: 7450 | R20: 45824 | S20: 약관 | V20: =P20*Q20 -> 484250
C21: 45821 | D21: =SUMIF($R$5:$R$269,$C21,$V$5:$V$269) -> 7616500 | E21: =SUMIF($U$5:$U$269,$C21,$V$5:$V$269) -> 0 | F21: =F20+D21-E21 -> 40955700 | G21: =G20-H21 -> 40890000 | H21: =SUMIF($I$7:$I$49,$C21,$J$7:$J$49) -> 0 | I21: 45841 | J21: 90000 | M21: 솔트룩스 | N21: 토스 | O21: 1 | P21: 10 | Q21: 48100 | R21: 45825 | S21: 약관 | V21: =P21*Q21 -> 481000
C22: 45822 | D22: =SUMIF($R$5:$R$269,$C22,$V$5:$V$269) -> 0 | E22: =SUMIF($U$5:$U$269,$C22,$V$5:$V$269) -> 0 | F22: =F21+D22-E22 -> 40955700 | G22: =G21-H22 -> 40890000 | H22: =SUMIF($I$7:$I$49,$C22,$J$7:$J$49) -> 0 | I22: 45848 | J22: 500000 | M22: 뉴프렉스 | N22: 토스 | O22: 1 | P22: 100 | Q22: 4530 | R22: 45826 | S22: 약관 | V22: =P22*Q22 -> 453000
C23: 45823 | D23: =SUMIF($R$5:$R$269,$C23,$V$5:$V$269) -> 0 | E23: =SUMIF($U$5:$U$269,$C23,$V$5:$V$269) -> 0 | F23: =F22+D23-E23 -> 40955700 | G23: =G22-H23 -> 40890000 | H23: =SUMIF($I$7:$I$49,$C23,$J$7:$J$49) -> 0 | I23: 45867 | J23: 260000 | M23: 솔트룩스 | N23: 토스 | O23: 1 | P23: 31 | Q23: 51000 | R23: 45826 | S23: 약관 | V23: =P23*Q23 -> 1581000
C24: 45824 | D24: =SUMIF($R$5:$R$269,$C24,$V$5:$V$269) -> 7620770 | E24: =SUMIF($U$5:$U$269,$C24,$V$5:$V$269) -> 11333000 | F24: =F23+D24-E24 -> 37243470 | G24: =G23-H24 -> 40440000 | H24: =SUMIF($I$7:$I$49,$C24,$J$7:$J$49) -> 450000 | I24: 45916 | J24: 800000 | M24: 솔트룩스 | N24: 토스 | O24: 1 | P24: 5 | Q24: 49800 | R24: 45826 | S24: 약관 | V24: =P24*Q24 -> 249000
C25: 45825 | D25: =SUMIF($R$5:$R$269,$C25,$V$5:$V$269) -> 4239250 | E25: =SUMIF($U$5:$U$269,$C25,$V$5:$V$269) -> 0 | F25: =F24+D25-E25 -> 41482720 | G25: =G24-H25 -> 40440000 | H25: =SUMIF($I$7:$I$49,$C25,$J$7:$J$49) -> 0 | I25: 45919 | J25: 400000 | M25: 코나아이 | N25: 토스 | O25: 1 | P25: 15 | Q25: 78000 | R25: 45826 | S25: 약관 | V25: =P25*Q25 -> 1170000
C26: 45826 | D26: =SUMIF($R$5:$R$269,$C26,$V$5:$V$269) -> 4555000 | E26: =SUMIF($U$5:$U$269,$C26,$V$5:$V$269) -> 6659270 | F26: =F25+D26-E26 -> 39378450 | G26: =G25-H26 -> 39640000 | H26: =SUMIF($I$7:$I$49,$C26,$J$7:$J$49) -> 800000 | I26: 45922 | J26: 780000 | M26: 코나아이 | N26: 토스 | O26: 1 | P26: 10 | Q26: 78400 | R26: 45826 | S26: 약관 | V26: =P26*Q26 -> 784000
C27: 45827 | D27: =SUMIF($R$5:$R$269,$C27,$V$5:$V$269) -> 556000 | E27: =SUMIF($U$5:$U$269,$C27,$V$5:$V$269) -> 0 | F27: =F26+D27-E27 -> 39934450 | G27: =G26-H27 -> 39640000 | H27: =SUMIF($I$7:$I$49,$C27,$J$7:$J$49) -> 0 | I27: 45926 | J27: 200000
C28: 45828 | D28: =SUMIF($R$5:$R$269,$C28,$V$5:$V$269) -> 0 | E28: =SUMIF($U$5:$U$269,$C28,$V$5:$V$269) -> 0 | F28: =F27+D28-E28 -> 39934450 | G28: =G27-H28 -> 39640000 | H28: =SUMIF($I$7:$I$49,$C28,$J$7:$J$49) -> 0 | I28: 45926 | J28: 464000
C29: 45829 | D29: =SUMIF($R$5:$R$269,$C29,$V$5:$V$269) -> 0 | E29: =SUMIF($U$5:$U$269,$C29,$V$5:$V$269) -> 0 | F29: =F28+D29-E29 -> 39934450 | G29: =G28-H29 -> 39640000 | H29: =SUMIF($I$7:$I$49,$C29,$J$7:$J$49) -> 0 | I29: 45931 | J29: 900700
C30: 45830 | D30: =SUMIF($R$5:$R$269,$C30,$V$5:$V$269) -> 0 | E30: =SUMIF($U$5:$U$269,$C30,$V$5:$V$269) -> 0 | F30: =F29+D30-E30 -> 39934450 | G30: =G29-H30 -> 39640000 | H30: =SUMIF($I$7:$I$49,$C30,$J$7:$J$49) -> 0 | I30: 45940 | J30: 100000
C31: 45831 | D31: =SUMIF($R$5:$R$269,$C31,$V$5:$V$269) -> 0 | E31: =SUMIF($U$5:$U$269,$C31,$V$5:$V$269) -> 0 | F31: =F30+D31-E31 -> 39934450 | G31: =G30-H31 -> 39640000 | H31: =SUMIF($I$7:$I$49,$C31,$J$7:$J$49) -> 0 | I31: 45940 | J31: 455100 | M31: 신테카바이오 | N31: 토스 | O31: 1 | P31: 10 | Q31: 6780 | R31: 45848 | S31: 약관 | V31: =P31*Q31 -> 67800
C32: 45832 | D32: =SUMIF($R$5:$R$269,$C32,$V$5:$V$269) -> 0 | E32: =SUMIF($U$5:$U$269,$C32,$V$5:$V$269) -> 2580200 | F32: =F31+D32-E32 -> 37354250 | G32: =G31-H32 -> 39440000 | H32: =SUMIF($I$7:$I$49,$C32,$J$7:$J$49) -> 200000 | I32: 45945 | J32: 520000 | M32: 코나아이 | N32: 토스 | O32: 1 | P32: 4 | Q32: 59300 | R32: 45848 | S32: 약관 | V32: =P32*Q32 -> 237200
C33: 45833 | D33: =SUMIF($R$5:$R$269,$C33,$V$5:$V$269) -> 2485000 | E33: =SUMIF($U$5:$U$269,$C33,$V$5:$V$269) -> 0 | F33: =F32+D33-E33 -> 39839250 | G33: =G32-H33 -> 39440000 | H33: =SUMIF($I$7:$I$49,$C33,$J$7:$J$49) -> 0 | I33: 45950 | J33: 72300 | M33: 한화손해보험 | N33: 토스 | O33: 1 | P33: 50 | Q33: 7320 | R33: 45855 | S33: 약관 | T33: 6600 | U33: 46057 | V33: =P33*Q33 -> 366000
C34: 45834 | D34: =SUMIF($R$5:$R$269,$C34,$V$5:$V$269) -> 0 | E34: =SUMIF($U$5:$U$269,$C34,$V$5:$V$269) -> 2611000 | F34: =F33+D34-E34 -> 37228250 | G34: =G33-H34 -> 39000000 | H34: =SUMIF($I$7:$I$49,$C34,$J$7:$J$49) -> 440000 | I34: 45957 | J34: 315000 | M34: 한화손해보험 | N34: 토스 | O34: 1 | P34: 20 | Q34: 6450 | R34: 45861 | S34: 약관 | T34: 6600 | U34: 46057 | V34: =P34*Q34 -> 129000
C35: 45835 | D35: =SUMIF($R$5:$R$269,$C35,$V$5:$V$269) -> 307500 | E35: =SUMIF($U$5:$U$269,$C35,$V$5:$V$269) -> 0 | F35: =F34+D35-E35 -> 37535750 | G35: =G34-H35 -> 39000000 | H35: =SUMIF($I$7:$I$49,$C35,$J$7:$J$49) -> 0 | I35: 45958 | J35: 570000 | M35: 한화손해보험 | N35: 토스 | O35: 1 | P35: 20 | Q35: 5930 | R35: 45880 | S35: 약관 | T35: 6600 | U35: 46057 | V35: =P35*Q35 -> 118600
C36: 45836 | D36: =SUMIF($R$5:$R$269,$C36,$V$5:$V$269) -> 0 | E36: =SUMIF($U$5:$U$269,$C36,$V$5:$V$269) -> 0 | F36: =F35+D36-E36 -> 37535750 | G36: =G35-H36 -> 39000000 | H36: =SUMIF($I$7:$I$49,$C36,$J$7:$J$49) -> 0 | I36: 45961 | J36: 1500000 | M36: 신테카바이오 | N36: 토스 | O36: 1 | P36: 22 | Q36: 5750 | R36: 45894 | S36: 약관 | V36: =P36*Q36 -> 126500
C37: 45837 | D37: =SUMIF($R$5:$R$269,$C37,$V$5:$V$269) -> 0 | E37: =SUMIF($U$5:$U$269,$C37,$V$5:$V$269) -> 0 | F37: =F36+D37-E37 -> 37535750 | G37: =G36-H37 -> 39000000 | H37: =SUMIF($I$7:$I$49,$C37,$J$7:$J$49) -> 0 | I37: 45971 | J37: 105400 | M37: 코나아이 | N37: 토스 | O37: 1 | P37: 7 | Q37: 52800 | R37: 45894 | S37: 약관 | V37: =P37*Q37 -> 369600
C38: 45838 | D38: =SUMIF($R$5:$R$269,$C38,$V$5:$V$269) -> 2548000 | E38: =SUMIF($U$5:$U$269,$C38,$V$5:$V$269) -> 3456500 | F38: =F37+D38-E38 -> 36627250 | G38: =G37-H38 -> 38250000 | H38: =SUMIF($I$7:$I$49,$C38,$J$7:$J$49) -> 750000 | I38: 45973 | J38: 937009 | M38: 한화손해보험 | N38: 토스 | O38: 1 | P38: 30 | Q38: 5350 | R38: 45894 | S38: 약관 | T38: 6600 | U38: 46057 | V38: =P38*Q38 -> 160500
C39: 45839 | D39: =SUMIF($R$5:$R$269,$C39,$V$5:$V$269) -> 2574700 | E39: =SUMIF($U$5:$U$269,$C39,$V$5:$V$269) -> 0 | F39: =F38+D39-E39 -> 39201950 | G39: =G38-H39 -> 38250000 | H39: =SUMIF($I$7:$I$49,$C39,$J$7:$J$49) -> 0 | I39: 45987 | J39: 400000 | M39: 한화손해보험 | N39: 토스 | O39: 1 | P39: 150 | Q39: 6370 | R39: 45916 | S39: 약관 | T39: 6600 | U39: 46057 | V39: =P39*Q39 -> 955500
C40: 45840 | D40: =SUMIF($R$5:$R$269,$C40,$V$5:$V$269) -> 0 | E40: =SUMIF($U$5:$U$269,$C40,$V$5:$V$269) -> 0 | F40: =F39+D40-E40 -> 39201950 | G40: =G39-H40 -> 38250000 | H40: =SUMIF($I$7:$I$49,$C40,$J$7:$J$49) -> 0 | I40: 45994 | J40: 530000 | M40: 한화손해보험 | N40: 토스 | O40: 1 | P40: 80 | Q40: 6070 | R40: 45917 | S40: 약관 | T40: 7000 | U40: 46063 | V40: =P40*Q40 -> 485600
C41: 45841 | D41: =SUMIF($R$5:$R$269,$C41,$V$5:$V$269) -> 0 | E41: =SUMIF($U$5:$U$269,$C41,$V$5:$V$269) -> 1839000 | F41: =F40+D41-E41 -> 37362950 | G41: =G40-H41 -> 38160000 | H41: =SUMIF($I$7:$I$49,$C41,$J$7:$J$49) -> 90000 | I41: 46003 | J41: 680000 | M41: 비보존제약 | N41: 토스 | O41: 1 | P41: 70 | Q41: 7240 | R41: 45918 | V41: =P41*Q41 -> 506800
C42: 45842 | D42: =SUMIF($R$5:$R$269,$C42,$V$5:$V$269) -> 365400 | E42: =SUMIF($U$5:$U$269,$C42,$V$5:$V$269) -> 0 | F42: =F41+D42-E42 -> 37728350 | G42: =G41-H42 -> 38160000 | H42: =SUMIF($I$7:$I$49,$C42,$J$7:$J$49) -> 0 | I42: 46010 | J42: 1050491 | M42: 비보존제약 | N42: 토스 | O42: 1 | P42: 50 | Q42: 7140 | R42: 45919 | V42: =P42*Q42 -> 357000
C43: 45843 | D43: =SUMIF($R$5:$R$269,$C43,$V$5:$V$269) -> 0 | E43: =SUMIF($U$5:$U$269,$C43,$V$5:$V$269) -> 0 | F43: =F42+D43-E43 -> 37728350 | G43: =G42-H43 -> 38160000 | H43: =SUMIF($I$7:$I$49,$C43,$J$7:$J$49) -> 0 | I43: 46021 | J43: 800000 | M43: 비보존제약 | N43: 토스 | O43: 1 | P43: 50 | Q43: 7000 | R43: 45919 | V43: =P43*Q43 -> 350000
...

Sheet 매도완료
K1: 수수료 0.015%(미래) 0.15%(한화) | M1: 매매세 매도금액*0.3%(`19/6월부터 0.25%)
B2: 종목 | C2: 거래유형 | D2: 적용 환율 | E2: 수량 | F2: 매수금액 | G2: 매수일자 | H2: 비고 | I2: 매도금액 | J2: 매도일자 | K2: 매수 수수료 | L2: 매도 수수료 | M2: 매매세 | N2: 배당금 | O2: 보유일수 | P2: 매수액 | Q2: 매도액 | R2: 기타 | S2: 손익 | T2: 손익률 | U2: 연간손익률 | V2: 비고
B3: ACE레버리지 | C3: 신한 | D3: =IF(OR($C3="신한",$C3="OTC",$C3="무상증자(신한)",$C3="토스",$C3="R토스"),1,"확인") -> 1 | E3: 100 | F3: 13360 | G3: 45944 | I3: 26500 | J3: 46041 | K3: =IF($C3="OTC",ROUNDDOWN($E3*$F3*0.000909187,-1),(IF($C3="신한",ROUNDDOWN($E3*$F3*0.000036396,-1),(IF($C3="토스",$E3*$F3*0.00015,(IF($C3="US",(IF($E3*$F3*0.0025>0.01,$E3*$F3*0.0025,0.01)),IF($C3="JP",(IF($E3*$F3*0.0025>1000,$E3*$F3*0.0025,1000)),(IF($C3="R토스",0,IF($C3="무상증자(신한)",0,""))))))))))) -> 40 | L3: =IF($C3="OTC",ROUNDDOWN($I3*$E3*0.000909187,-1),(IF($C3="신한",ROUNDDOWN($I3*$E3*0.000036396,-1),(IF($C3="토스",$I3*$E3*0.00015,(IF($C3="US",(IF($I3*$E3*0.0025>0.01,$I3*$E3*0.0025,0.01)),(IF($C3="JP",(IF($I3*$E3*0.0025>1000,$I3*$E3*0.0025,1000)),(IF($C3="R토스",$I3*$E3*0.00015,(IF($C3="무상증자(신한)",ROUNDDOWN($I3*$E3*0.000036396,-1),""))))))))))))) -> 90 | M3: =Q3*0.002 -> 5300 | N3: =236*E3 -> 23600 | P3: =$E3*$F3*$D3 -> 1336000 | Q3: =$E3*$I3*$D3 -> 2650000 | R3: =($N3-$K3-$L3-$M3)*$D3 -> 18170 | S3: =IF(Q3=0,0,Q3-P3+R3) -> 1332170 | T3: =S3/P3 -> 0.99713323
B4: ARCHER AVIATION | C4: 한화 | D4: 1102.9 | E4: 100 | F4: 12.2 | G4: 44252 | I4: 11 | J4: 45933 | K4: =E4*F4*0.001 -> 1.22 | L4: =ROUNDDOWN(E4*I4*0.001, 2) -> 1.1 | M4: =ROUNDUP((E4*I4*0.0000221),2) -> 0.03 | O4: =IF(J4="","",J4-G4+1) -> 1682 | P4: =$E4*$F4*$D4 -> 1345538 | Q4: =$E4*$I4*$D4 -> 1213190 | R4: =($N4-$K4-$L4-$M4)*$D4 -> -2591.815 | S4: =IF(Q4=0,"",Q4-P4+R4) -> -134939.82 | T4: =IF(Q4=0,"",S4/P4) -> -0.10028689
B5: ARCHER AVIATION | C5: 한화 | D5: 1102.9 | E5: 8 | F5: 6.4 | G5: 44505 | I5: 11 | J5: 45933 | K5: =E5*F5*0.001 -> 0.0512 | L5: =ROUNDDOWN(E5*I5*0.001, 2) -> 0.08 | M5: =ROUNDUP((E5*I5*0.0000221),2) -> 0.01 | O5: =IF(J5="","",J5-G5+1) -> 1429 | P5: =$E5*$F5*$D5 -> 56468.48 | Q5: =$E5*$I5*$D5 -> 97055.2 | R5: =($N5-$K5-$L5-$M5)*$D5 -> -155.72948 | S5: =IF(Q5=0,"",Q5-P5+R5) -> 40430.991 | T5: =IF(Q5=0,"",S5/P5) -> 0.71599219
B6: AT&T | C6: 한화 | D6: 1231.3 | E6: 30 | F6: 29.8 | G6: 43942 | I6: 31.3 | J6: 44174 | K6: =ROUNDDOWN(E6*F6*0.001, 2) -> 0.89 | L6: =ROUNDDOWN(E6*I6*0.001, 2) -> 0.93 | M6: =ROUNDUP((E6*I6*0.0000221),2) -> 0.03 | N6: =(15.6-2.34)+(15.6-2.34) -> 26.52 | O6: =IF(J6="","",J6-G6+1) -> 233 | P6: =$E6*$F6*$D6 -> 1100782.2 | Q6: =$E6*$I6*$D6 -> 1156190.7 | R6: =($N6-$K6-$L6-$M6)*$D6 -> 30376.171 | S6: =IF(Q6=0,"",Q6-P6+R6) -> 85784.671 | T6: =IF(Q6=0,"",S6/P6) -> 0.077930649 | V6: =K6/(E6*F6) -> 0.00099552573
B7: Cassava Science | C7: 한화 | D7: 1102.9 | E7: 13 | F7: 95 | G7: 44230 | I7: 3.7 | J7: 45933 | K7: =E7*F7*0.001 -> 1.235 | L7: =ROUNDDOWN(E7*I7*0.001, 2) -> 0.04 | M7: =ROUNDUP((E7*I7*0.0000221),2) -> 0.01 | O7: =IF(J7="","",J7-G7+1) -> 1704 | P7: =$E7*$F7*$D7 -> 1362081.5 | Q7: =$E7*$I7*$D7 -> 53049.49 | R7: =($N7-$K7-$L7-$M7)*$D7 -> -1417.2265 | S7: =IF(Q7=0,"",Q7-P7+R7) -> -1310449.2 | T7: =IF(Q7=0,"",S7/P7) -> -0.96209312 | X7: =E7*I7*0.0000221 -> 0.00106301 | Y7: =ROUNDUP(E7*I7*0.000021,2) -> 0.01
B8: Coupang | C8: R토스 | X8: =E8*I8*0.0000221 -> 0 | Y8: =ROUNDUP(E8*I8*0.000021,2) -> 0
B9: Discovery-A | C9: US | D9: 1129.2 | E9: 80 | F9: 42.37 | G9: 44291 | I9: 24.6 | J9: 44508 | K9: =IF($C9="OTC",ROUNDDOWN($E9*$F9*0.000909187,-1),(IF($C9="신한",ROUNDDOWN($E9*$F9*0.000036396,-1),(IF($C9="토스",$E9*$F9*0.00015,(IF($C9="US",(IF($E9*$F9*0.0025>0.01,$E9*$F9*0.0025,0.01)),IF($C9="JP",(IF($E9*$F9*0.0025>1000,$E9*$F9*0.0025,1000)),(IF($C9="R토스",0,IF($C9="무상증자(신한)",0,""))))))))))) -> 8.474 | L9: =IF($C9="OTC",ROUNDDOWN($I9*$E9*0.000909187,-1),(IF($C9="신한",ROUNDDOWN($I9*$E9*0.000036396,-1),(IF($C9="토스",$I9*$E9*0.00015,(IF($C9="US",(IF($I9*$E9*0.0025>0.01,$I9*$E9*0.0025,0.01)),(IF($C9="JP",(IF($I9*$E9*0.0025>1000,$I9*$E9*0.0025,1000)),(IF($C9="R토스",$I9*$E9*0.00015,(IF($C9="무상증자(신한)",ROUNDDOWN($I9*$E9*0.000036396,-1),""))))))))))))) -> 4.92 | M9: =E9*I9*0.0000051 -> 0.0100368 | O9: =J9-G9+1 -> 218 | P9: =$E9*$F9*$D9 -> 3827536.3 | Q9: =$E9*$I9*$D9 -> 2222265.6 | R9: =($N9-$K9-$L9-$M9)*$D9 -> -15135.838 | S9: =IF(Q9=0,0,Q9-P9+R9) -> -1620406.6 | T9: =S9/P9 -> -0.42335498 | X9: =E9*I9*0.0000221 -> 0.0434928 | Y9: =ROUNDUP(E9*I9*0.000021,2) -> 0.05
B10: Intellia Therapeautics | C10: US | D10: 1196.2 | E10: 10 | F10: 135.69 | G10: 44505 | I10: 18.8 | J10: 45931 | K10: =IF($C10="OTC",ROUNDDOWN($E10*$F10*0.000909187,-1),(IF($C10="신한",ROUNDDOWN($E10*$F10*0.000036396,-1),(IF($C10="토스",$E10*$F10*0.00015,(IF($C10="US",(IF($E10*$F10*0.0025>0.01,$E10*$F10*0.0025,0.01)),IF($C10="JP",(IF($E10*$F10*0.0025>1000,$E10*$F10*0.0025,1000)),(IF($C10="R토스",0,IF($C10="무상증자(신한)",0,""))))))))))) -> 3.39225 | L10: =IF($C10="OTC",ROUNDDOWN($I10*$E10*0.000909187,-1),(IF($C10="신한",ROUNDDOWN($I10*$E10*0.000036396,-1),(IF($C10="토스",$I10*$E10*0.00015,(IF($C10="US",(IF($I10*$E10*0.0025>0.01,$I10*$E10*0.0025,0.01)),(IF($C10="JP",(IF($I10*$E10*0.0025>1000,$I10*$E10*0.0025,1000)),(IF($C10="R토스",$I10*$E10*0.00015,(IF($C10="무상증자(신한)",ROUNDDOWN($I10*$E10*0.000036396,-1),""))))))))))))) -> 0.47 | M10: =E10*I10*0.0000051 -> 0.0009588 | O10: =J10-G10+1 -> 1427 | P10: =$E10*$F10*$D10 -> 1623123.8 | Q10: =$E10*$I10*$D10 -> 224885.6 | R10: =($N10-$K10-$L10-$M10)*$D10 -> -4621.1704 | S10: =IF(Q10=0,0,Q10-P10+R10) -> -1402859.4 | T10: =S10/P10 -> -0.86429598 | X10: =E10*I10*0.0000221 -> 0.0041548 | Y10: =ROUNDUP(X10,2) -> 0.01
B11: LUCKIN COFFEE INC | C11: 한화 | D11: 1182.6 | E11: 40 | F11: 30.65 | G11: 43818 | I11: 35.23 | J11: 43826 | K11: =ROUNDDOWN(E11*F11*0.001, 2) -> 1.22 | L11: =ROUNDDOWN(E11*I11*0.001, 2) -> 1.4 | M11: =ROUNDUP((E11*I11*0.0000221),2) -> 0.04 | O11: =IF(J11="","",J11-G11+1) -> 9 | P11: =$E11*$F11*$D11 -> 1449867.6 | Q11: =$E11*$I11*$D11 -> 1666519.9 | R11: =($N11-$K11-$L11-$M11)*$D11 -> -3145.716 | S11: =IF(Q11=0,"",Q11-P11+R11) -> 213506.6 | T11: =IF(Q11=0,"",S11/P11) -> 0.14725938 | V11: =K11/(E11*F11) -> 0.00099510604 | AH11: 거래 유형
B12: LUCKIN COFFEE INC | C12: 한화 | D12: 1230.9 | E12: 50 | F12: 30.2 | G12: 43920 | I12: 0 | J12: 44013 | K12: =ROUNDDOWN(E12*F12*0.001, 2) -> 1.51 | L12: =ROUNDDOWN(E12*I12*0.001, 2) -> 0 | M12: =ROUNDUP((E12*I12*0.0000221),2) -> 0 | O12: =IF(J12="","",J12-G12+1) -> 94 | P12: =$E12*$F12*$D12 -> 1858659 | Q12: =$E12*$I12*$D12 -> 0 | R12: =($N12-$K12-$L12-$M12)*$D12 -> -1858.659 | S12: =Q12-P12+R12 -> -1860517.7 | T12: =S12/P12 -> -1.001 | V12: =K12/(E12*F12) -> 0.001
B13: ㄴ장외종목변경 | C13: LKNCY.OT | E13: 50 | F13: 0 | G13: 44013 | K13: 1 | L13: =ROUNDDOWN(E13*I13*0.001, 2) -> 0 | M13: =ROUNDUP((E13*I13*0.0000221),2) -> 0 | N13: =-1-1-1-1-1-1.01 -> -6.01 | O13: =IF(J13="","",J13-G13+1) | P13: =$E13*$F13*$D13 -> 0 | Q13: =$E13*$I13*$D13 -> 0 | R13: =($N13-$K13-$L13-$M13)*$D13 -> 0 | S13: =IF(Q13=0,"",Q13-P13+R13) | T13: =IF(Q13=0,"",S13/P13) | V13: =K13/(E13*F13) -> #DIV/0!
B14: 룰루레몬 애슬릿티카 | C14: 한화 | D14: 1182.6 | E14: 5 | F14: 223.4 | G14: 43817 | I14: 315.2 | J14: 44029 | K14: =ROUNDDOWN(E14*F14*0.001, 2) -> 1.11 | L14: =ROUNDDOWN(E14*I14*0.001, 2) -> 1.57 | M14: =ROUNDUP((E14*I14*0.0000221),2) -> 0.04 | O14: =IF(J14="","",J14-G14+1) -> 213 | P14: =$E14*$F14*$D14 -> 1320964.2 | Q14: =$E14*$I14*$D14 -> 1863777.6 | R14: =($N14-$K14-$L14-$M14)*$D14 -> -3216.672 | S14: =IF(Q14=0,"",Q14-P14+R14) -> 539596.73 | T14: =IF(Q14=0,"",S14/P14) -> 0.40848702 | V14: =K14/(E14*F14) -> 0.00099373321
B15: 넥슨(JP:3659) | C15: JP | D15: 11.3571 | E15: 200 | F15: 2800 | G15: 44046 | I15: 2952 | J15: 44131 | K15: 0 | L15: =IF($C15="OTC",ROUNDDOWN($I15*$E15*0.000909187,-1),(IF($C15="신한",ROUNDDOWN($I15*$E15*0.000036396,-1),(IF($C15="토스",$I15*$E15*0.00015,(IF($C15="US",(IF($I15*$E15*0.0025>0.01,$I15*$E15*0.0025,0.01)),(IF($C15="JP",(IF($I15*$E15*0.0025>1000,$I15*$E15*0.0025,1000)),(IF($C15="R토스",$I15*$E15*0.00015,(IF($C15="무상증자(신한)",ROUNDDOWN($I15*$E15*0.000036396,-1),""))))))))))))) -> 1476 | O15: =J15-G15+1 -> 86 | P15: =$E15*$F15*$D15 -> 6359976 | Q15: =$E15*$I15*$D15 -> 6705231.8 | R15: =($N15-$K15-$L15-$M15)*$D15 -> -16763.08 | S15: =IF(Q15=0,0,Q15-P15+R15) -> 328492.76 | T15: =S15/P15 -> 0.05165
B16: 넥슨(JP:3659) | C16: JP | D16: 11.3571 | E16: 100 | F16: 2800 | G16: 44046 | I16: 2952 | J16: 44131 | K16: =IF($C16="OTC",ROUNDDOWN($E16*$F16*0.000909187,-1),(IF($C16="신한",ROUNDDOWN($E16*$F16*0.000036396,-1),(IF($C16="토스",$E16*$F16*0.00015,(IF($C16="US",(IF($E16*$F16*0.0025>0.01,$E16*$F16*0.0025,0.01)),IF($C16="JP",(IF($E16*$F16*0.0025>1000,$E16*$F16*0.0025,1000)),(IF($C16="R토스",0,IF($C16="무상증자(신한)",0,""))))))))))) -> 1000 | L16: =(E16+E15)*I16*0.0025-L15 -> 738 | O16: =J16-G16+1 -> 86 | P16: =$E16*$F16*$D16 -> 3179988 | Q16: =$E16*$I16*$D16 -> 3352615.9 | R16: =($N16-$K16-$L16-$M16)*$D16 -> -19738.64 | S16: =IF(Q16=0,0,Q16-P16+R16) -> 152889.28 | T16: =S16/P16 -> 0.048078571
B17: 넥슨(JP:3659) | C17: JP | D17: 11.3571 | E17: 100 | F17: 2540 | G17: 44148 | I17: 3200 | J17: 44166 | K17: =IF($C17="OTC",ROUNDDOWN($E17*$F17*0.000909187,-1),(IF($C17="신한",ROUNDDOWN($E17*$F17*0.000036396,-1),(IF($C17="토스",$E17*$F17*0.00015,(IF($C17="US",(IF($E17*$F17*0.0025>0.01,$E17*$F17*0.0025,0.01)),IF($C17="JP",(IF($E17*$F17*0.0025>1000,$E17*$F17*0.0025,1000)),(IF($C17="R토스",0,IF($C17="무상증자(신한)",0,""))))))))))) -> 1000 | L17: =IF($C17="OTC",ROUNDDOWN($I17*$E17*0.000909187,-1),(IF($C17="신한",ROUNDDOWN($I17*$E17*0.000036396,-1),(IF($C17="토스",$I17*$E17*0.00015,(IF($C17="US",(IF($I17*$E17*0.0025>0.01,$I17*$E17*0.0025,0.01)),(IF($C17="JP",(IF($I17*$E17*0.0025>1000,$I17*$E17*0.0025,1000)),(IF($C17="R토스",$I17*$E17*0.00015,(IF($C17="무상증자(신한)",ROUNDDOWN($I17*$E17*0.000036396,-1),""))))))))))))) -> 1000 | O17: =J17-G17+1 -> 19 | P17: =$E17*$F17*$D17 -> 2884703.4 | Q17: =$E17*$I17*$D17 -> 3634272 | R17: =($N17-$K17-$L17-$M17)*$D17 -> -22714.2 | S17: =IF(Q17=0,0,Q17-P17+R17) -> 726854.4 | T17: =S17/P17 -> 0.2519685
B18: 넥슨(JP:3659) | C18: JP | D18: 11.3571 | E18: 100 | F18: 3070 | G18: 44167 | I18: 3300 | J18: 44209 | K18: =IF($C18="OTC",ROUNDDOWN($E18*$F18*0.000909187,-1),(IF($C18="신한",ROUNDDOWN($E18*$F18*0.000036396,-1),(IF($C18="토스",$E18*$F18*0.00015,(IF($C18="US",(IF($E18*$F18*0.0025>0.01,$E18*$F18*0.0025,0.01)),IF($C18="JP",(IF($E18*$F18*0.0025>1000,$E18*$F18*0.0025,1000)),(IF($C18="R토스",0,IF($C18="무상증자(신한)",0,""))))))))))) -> 1000 | L18: =IF($C18="OTC",ROUNDDOWN($I18*$E18*0.000909187,-1),(IF($C18="신한",ROUNDDOWN($I18*$E18*0.000036396,-1),(IF($C18="토스",$I18*$E18*0.00015,(IF($C18="US",(IF($I18*$E18*0.0025>0.01,$I18*$E18*0.0025,0.01)),(IF($C18="JP",(IF($I18*$E18*0.0025>1000,$I18*$E18*0.0025,1000)),(IF($C18="R토스",$I18*$E18*0.00015,(IF($C18="무상증자(신한)",ROUNDDOWN($I18*$E18*0.000036396,-1),""))))))))))))) -> 1000 | N18: =250-38 -> 212 | O18: =J18-G18+1 -> 43 | P18: =$E18*$F18*$D18 -> 3486629.7 | Q18: =$E18*$I18*$D18 -> 3747843 | R18: =($N18-$K18-$L18-$M18)*$D18 -> -20306.495 | S18: =IF(Q18=0,0,Q18-P18+R18) -> 240906.81 | T18: =S18/P18 -> 0.069094463
B19: PROETF SHORT VIX SHORT TERM FUTURES ETF | C19: 한화 | D19: 1230.9 | E19: 15 | F19: 29.75 | G19: 43927 | I19: 35.4 | J19: 43990 | K19: =ROUNDDOWN(E19*F19*0.001, 2) -> 0.44 | L19: =ROUNDDOWN(E19*I19*0.001, 2) -> 0.53 | M19: =ROUNDUP((E19*I19*0.0000221),2) -> 0.02 | O19: =IF(J19="","",J19-G19+1) -> 64 | P19: =$E19*$F19*$D19 -> 549289.12 | Q19: =$E19*$I19*$D19 -> 653607.9 | R19: =($N19-$K19-$L19-$M19)*$D19 -> -1218.591 | S19: =IF(Q19=0,"",Q19-P19+R19) -> 103100.18 | T19: =IF(Q19=0,"",S19/P19) -> 0.18769748 | V19: =K19/(E19*F19) -> 0.0009859944
B20: PROETF ULTRA OIL & GAS | C20: 한화 | D20: 1230.9 | E20: 30 | F20: 44 | G20: 43927 | I20: 77 | J20: 44183 | K20: =ROUNDDOWN(E20*F20*0.001, 2) -> 1.32 | L20: =ROUNDDOWN(E20*I20*0.001, 2) -> 2.31 | M20: =ROUNDUP((E20*I20*0.0000221),2) -> 0.06 | N20: =(18.81-2.82)+(18.2-2.73) -> 31.46 | O20: =IF(J20="","",J20-G20+1) -> 257 | P20: =$E20*$F20*$D20 -> 1624788 | Q20: =$E20*$I20*$D20 -> 2843379 | R20: =($N20-$K20-$L20-$M20)*$D20 -> 34182.093 | S20: =IF(Q20=0,"",Q20-P20+R20) -> 1252773.1 | T20: =IF(Q20=0,"",S20/P20) -> 0.77103788 | V20: =K20/(E20*F20) -> 0.001
B21: PROETF VIX SHORT-TERM FUTURES ETF | C21: 한화 | D21: 1147.5 | E21: 42 | F21: 23.5 | G21: 43564 | I21: 25 | J21: 43696 | K21: =ROUNDDOWN(E21*F21*0.001, 2) -> 0.98 | L21: =ROUNDDOWN(E21*I21*0.001, 2) -> 1.05 | M21: =ROUNDUP((E21*I21*0.0000221),2) -> 0.03 | O21: =IF(J21="","",J21-G21+1) -> 133 | P21: =$E21*$F21*$D21 -> 1132582.5 | Q21: =$E21*$I21*$D21 -> 1204875 | R21: =($N21-$K21-$L21-$M21)*$D21 -> -2363.85 | S21: =IF(Q21=0,"",Q21-P21+R21) -> 69928.65 | T21: =IF(Q21=0,"",S21/P21) -> 0.061742655 | V21: =K21/(E21*F21) -> 0.0009929078
B22: PROETF VIX SHORT-TERM FUTURES ETF | C22: 한화 | D22: 1147.5 | E22: 51 | F22: 20.78 | G22: 43718 | I22: 19.5 | J22: 43896 | K22: =ROUNDDOWN(E22*F22*0.001, 2) -> 1.05 | L22: =ROUNDDOWN(E22*I22*0.001, 2) -> 0.99 | M22: =ROUNDUP((E22*I22*0.0000221),2) -> 0.03 | O22: =IF(J22="","",J22-G22+1) -> 179 | P22: =$E22*$F22*$D22 -> 1216097.6 | Q22: =$E22*$I22*$D22 -> 1141188.8 | R22: =($N22-$K22-$L22-$M22)*$D22 -> -2375.325 | S22: =IF(Q22=0,"",Q22-P22+R22) -> -77284.125 | T22: =IF(Q22=0,"",S22/P22) -> -0.063550926 | V22: =K22/(E22*F22) -> 0.00099077167
B23: PROETF VIX SHORT-TERM FUTURES ETF | C23: 한화 | D23: 1180.1 | E23: 70 | F23: 15.25 | G23: 43783 | I23: 19.5 | J23: 43896 | K23: =ROUNDDOWN(E23*F23*0.001, 2) -> 1.06 | L23: =ROUNDDOWN(E23*I23*0.001, 2) -> 1.36 | M23: =ROUNDUP((E23*I23*0.0000221),2) -> 0.04 | O23: =IF(J23="","",J23-G23+1) -> 114 | P23: =$E23*$F23*$D23 -> 1259756.8 | Q23: =$E23*$I23*$D23 -> 1610836.5 | R23: =($N23-$K23-$L23-$M23)*$D23 -> -2903.046 | S23: =IF(Q23=0,"",Q23-P23+R23) -> 348176.7 | T23: =IF(Q23=0,"",S23/P23) -> 0.27638407 | V23: =K23/(E23*F23) -> 0.00099297424
B24: PROETF VIX SHORT-TERM FUTURES ETF | C24: 한화 | D24: 1181.8 | E24: 40 | F24: 12.25 | G24: 43843 | I24: 19.5 | J24: 43896 | K24: =ROUNDDOWN(E24*F24*0.001, 2) -> 0.49 | L24: =ROUNDDOWN(E24*I24*0.001, 2) -> 0.78 | M24: =ROUNDUP((E24*I24*0.0000221),2) -> 0.02 | O24: =IF(J24="","",J24-G24+1) -> 54 | P24: =$E24*$F24*$D24 -> 579082 | Q24: =$E24*$I24*$D24 -> 921804 | R24: =($N24-$K24-$L24-$M24)*$D24 -> -1524.522 | S24: =IF(Q24=0,"",Q24-P24+R24) -> 341197.48 | T24: =IF(Q24=0,"",S24/P24) -> 0.58920408 | V24: =K24/(E24*F24) -> 0.001
B25: S&P BIO | C25: 한화 | D25: 1102.9 | E25: 16 | F25: 142.1 | G25: 44202 | I25: 170.5 | J25: 44238 | K25: =E25*F25*0.001 -> 2.2736 | L25: =ROUNDDOWN(E25*I25*0.001, 2) -> 2.72 | M25: =ROUNDUP((E25*I25*0.0000221),2) -> 0.07 | O25: =IF(J25="","",J25-G25+1) -> 37 | P25: =$E25*$F25*$D25 -> 2507553.4 | Q25: =$E25*$I25*$D25 -> 3008711.2 | R25: =($N25-$K25-$L25-$M25)*$D25 -> -5584.6444 | S25: =IF(Q25=0,"",Q25-P25+R25) -> 495573.12 | T25: =IF(Q25=0,"",S25/P25) -> 0.19763213
B26: S&P BIO | C26: 한화 | D26: 1102.9 | E26: 9 | F26: 158.38 | G26: 44243 | I26: 103.5 | J26: 45933 | K26: =E26*F26*0.001 -> 1.42542 | L26: =ROUNDDOWN(E26*I26*0.001, 2) -> 0.93 | M26: =ROUNDUP((E26*I26*0.0000221),2) -> 0.03 | N26: =(0.36-0.05)+0.02+(0.12-0.02)+(1.03-0.15)+(0.14-0.02)+0.02+(0.05-0.01)+(0.07-0.01) -> 1.55 | O26: =IF(J26="","",J26-G26+1) -> 1691 | P26: =$E26*$F26*$D26 -> 1572095.7 | Q26: =$E26*$I26*$D26 -> 1027351.4 | R26: =($N26-$K26-$L26-$M26)*$D26 -> -921.38472 | S26: =IF(Q26=0,"",Q26-P26+R26) -> -545665.75 | T26: =IF(Q26=0,"",S26/P26) -> -0.34709448
B27: VANGUARD HEALTH CARE ETF | C27: 한화 | D27: 1182.6 | E27: 7 | F27: 192.5 | G27: 43833 | I27: 198.2 | J27: 44022 | K27: =ROUNDDOWN(E27*F27*0.001, 2) -> 1.34 | L27: =ROUNDDOWN(E27*I27*0.001, 2) -> 1.38 | M27: =ROUNDUP((E27*I27*0.0000221),2) -> 0.04 | N27: =(3.12-0.46)+(5.29-0.79) -> 7.16 | O27: =IF(J27="","",J27-G27+1) -> 190 | P27: =$E27*$F27*$D27 -> 1593553.5 | Q27: =$E27*$I27*$D27 -> 1640739.2 | R27: =($N27-$K27-$L27-$M27)*$D27 -> 5203.44 | S27: =IF(Q27=0,"",Q27-P27+R27) -> 52389.18 | T27: =IF(Q27=0,"",S27/P27) -> 0.032875696 | V27: =K27/(E27*F27) -> 0.00099443414
B28: 바이오젠 | C28: 한화 | D28: 1231.3 | E28: 4 | F28: 264.9 | G28: 44020 | I28: 281.65 | J28: 44090 | K28: =ROUNDDOWN(E28*F28*0.001, 2) -> 1.05 | L28: =ROUNDDOWN(E28*I28*0.001, 2) -> 1.12 | M28: =ROUNDUP((E28*I28*0.0000221),2) -> 0.03 | O28: =IF(J28="","",J28-G28+1) -> 71 | P28: =$E28*$F28*$D28 -> 1304685.5 | Q28: =$E28*$I28*$D28 -> 1387182.6 | R28: =($N28-$K28-$L28-$M28)*$D28 -> -2708.86 | S28: =IF(Q28=0,"",Q28-P28+R28) -> 79788.24 | T28: =IF(Q28=0,"",S28/P28) -> 0.061155153 | V28: =K28/(E28*F28) -> 0.00099093998
B29: 블랙록 | C29: 한화 | D29: 1181.8 | E29: 1 | F29: 520 | G29: 43847 | I29: 541 | J29: 44015 | K29: =ROUNDDOWN(E29*F29*0.001, 2) -> 0.52 | L29: =ROUNDDOWN(E29*I29*0.001, 2) -> 0.54 | M29: =ROUNDUP((E29*I29*0.0000221),2) -> 0.02 | N29: =(3.63-0.54)+(3.63-0.54) -> 6.18 | O29: =IF(J29="","",J29-G29+1) -> 169 | P29: =$E29*$F29*$D29 -> 614536 | Q29: =$E29*$I29*$D29 -> 639353.8 | R29: =($N29-$K29-$L29-$M29)*$D29 -> 6027.18 | S29: =IF(Q29=0,"",Q29-P29+R29) -> 30844.98 | T29: =IF(Q29=0,"",S29/P29) -> 0.050192308 | V29: =K29/(E29*F29) -> 0.001
B30: BNK금융지주 | C30: 한화 | E30: 50 | F30: 8620 | G30: 42608 | I30: 8860 | J30: 42618 | K30: =ROUNDDOWN(E30*F30*0.0015,-1) -> 640 | L30: =ROUNDDOWN(I30*E30*0.0015,-1) -> 660 | M30: =I30*E30*0.003 -> 1329 | O30: =J30-G30+1 -> 11 | P30: =F30*E30 -> 431000 | Q30: =I30*E30 -> 443000 | R30: =N30-K30-L30-M30 -> -2629 | S30: =IF(Q30=0,0,Q30-P30+R30) -> 9371 | T30: =S30/P30 -> 0.021742459 | U30: =T30*365/O30 -> 0.72145433
B31: C&S자산관리 | C31: 한화 | E31: 250 | F31: 4020 | G31: 42585 | I31: 4250 | J31: 42587 | K31: =ROUNDDOWN(E31*F31*0.0015,-1) -> 1500 | L31: =ROUNDDOWN(I31*E31*0.0015,-1) -> 1590 | M31: =I31*E31*0.003 -> 3187.5 | O31: =J31-G31+1 -> 3 | P31: =F31*E31 -> 1005000 | Q31: =I31*E31 -> 1062500 | R31: =N31-K31-L31-M31 -> -6277.5 | S31: =IF(Q31=0,0,Q31-P31+R31) -> 51222.5 | T31: =S31/P31 -> 0.050967662 | U31: =T31*365/O31 -> 6.2010655
B32: C&우방 | C32: 한투 | E32: 20 | F32: 5250 | G32: 39322 | I32: 110 | J32: 39940 | K32: =ROUNDDOWN(E32*F32*0.005,-1) -> 520 | L32: =ROUNDDOWN(I32*E32*0.005,-1) -> 10 | M32: =I32*E32*0.003 -> 6.6 | O32: =J32-G32+1 -> 619 | P32: =F32*E32 -> 105000 | Q32: =I32*E32 -> 2200 | R32: =N32-K32-L32-M32 -> -536.6 | S32: =IF(Q32=0,0,Q32-P32+R32) -> -103336.6 | T32: =S32/P32 -> -0.9841581 | U32: =T32*365/O32 -> -0.58031939
B33: CJ인터넷 | C33: 미래에셋 | E33: 10 | F33: 9510 | G33: 39758 | I33: 11000 | J33: 39783 | K33: 20 | L33: 30 | O33: =J33-G33+1 -> 26 | P33: =F33*E33 -> 95100 | Q33: =I33*E33 -> 110000 | R33: =N33-K33-L33-M33 -> -50 | S33: =IF(Q33=0,0,Q33-P33+R33) -> 14850 | T33: =S33/P33 -> 0.15615142 | U33: =T33*365/O33 -> 2.1921257 | X33: =E33*I33*0.0000221 -> 2.431 | Y33: =ROUNDUP(E33*I33*0.000021,2) -> 2.31
B34: CJ제일제당 | C34: 미래에셋 | E34: 2 | F34: 140000 | G34: 39927 | I34: 170000 | J34: 39945 | K34: 80 | L34: 90 | O34: =J34-G34+1 -> 19 | P34: =F34*E34 -> 280000 | Q34: =I34*E34 -> 340000 | R34: =N34-K34-L34-M34 -> -170 | S34: =IF(Q34=0,0,Q34-P34+R34) -> 59830 | T34: =S34/P34 -> 0.21367857 | U34: =T34*365/O34 -> 4.1048778 | X34: =E34*I34*0.0000221 -> 7.514 | Y34: =ROUNDUP(E34*I34*0.000021,2) -> 7.14
B35: DSC인베스트먼트 | C35: 한화 | E35: 500 | F35: 2920 | G35: 43862 | I35: 3200 | J35: 43984 | K35: =ROUNDDOWN(E35*F35*0.0015,-1) -> 2190 | L35: =ROUNDDOWN(I35*E35*0.0015,-1) -> 2400 | M35: =ROUNDDOWN(I35*E35*0.0025, ) -> 4000 | O35: =J35-G35+1 -> 123 | P35: =F35*E35 -> 1460000 | Q35: =I35*E35 -> 1600000 | R35: =N35-K35-L35-M35 -> -8590 | S35: =IF(Q35=0,0,Q35-P35+R35) -> 131410 | T35: =S35/P35 -> 0.090006849 | U35: =T35*365/O35 -> 0.2670935 | X35: =E35*I35*0.0000221 -> 35.36 | Y35: =ROUNDUP(E35*I35*0.000021,2) -> 33.6
B36: GRT | C36: 한화 | E36: 400 | F36: 2600 | G36: 43300 | I36: 2950 | J36: 44832 | K36: =ROUNDDOWN(E36*F36*0.0015,-1) -> 1560 | L36: =ROUNDDOWN(I36*E36*0.0015,-1) -> 1770 | M36: =ROUNDDOWN(I36*E36*0.0025, ) -> 2950 | O36: =J36-G36+1 -> 1533 | P36: =F36*E36 -> 1040000 | Q36: =I36*E36 -> 1180000 | R36: =N36-K36-L36-M36 -> -6280 | S36: =IF(Q36=0,0,Q36-P36+R36) -> 133720 | T36: =S36/P36 -> 0.12857692 | U36: =T36*365/O36 -> 0.030613553 | X36: =E36*I36*0.0000221 -> 26.078 | Y36: =ROUNDUP(E36*I36*0.000021,2) -> 24.78
B37: GS | C37: 미래에셋 | E37: 10 | F37: 31000 | G37: 39961 | I37: 32100 | J37: 40025 | K37: 80 | L37: 90 | O37: =J37-G37+1 -> 65 | P37: =F37*E37 -> 310000 | Q37: =I37*E37 -> 321000 | R37: =N37-K37-L37-M37 -> -170 | S37: =IF(Q37=0,0,Q37-P37+R37) -> 10830 | T37: =S37/P37 -> 0.034935484 | U37: =T37*365/O37 -> 0.19617618 | X37: =E37*I37*0.0000221 -> 7.0941 | Y37: =ROUNDUP(E37*I37*0.000021,2) -> 6.75
B38: GS | C38: 미래에셋 | E38: 40 | F38: 43900 | G38: 41792 | I38: 46700 | J38: 41851 | K38: =ROUNDDOWN(E38*F38*0.00015,-1) -> 260 | L38: =ROUNDDOWN(I38*E38*0.00015,-1) -> 280 | M38: =I38*E38*0.003 -> 5604 | O38: =J38-G38+1 -> 60 | P38: =F38*E38 -> 1756000 | Q38: =I38*E38 -> 1868000 | R38: =N38-K38-L38-M38 -> -6144 | S38: =IF(Q38=0,0,Q38-P38+R38) -> 105856 | T38: =S38/P38 -> 0.06028246 | U38: =T38*365/O38 -> 0.3667183 | X38: =E38*I38*0.0000221 -> 41.2828 | Y38: =ROUNDUP(E38*I38*0.000021,2) -> 39.23
B39: HD현대일렉트릭 | C39: 토스 | D39: =IF(OR($C39="신한",$C39="OTC",$C39="무상증자(신한)",$C39="토스",$C39="R토스"),1,"확인") -> 1 | E39: 2 | F39: 425000 | G39: 45819 | H39: 약관 | I39: 454000 | J39: 45824 | K39: =IF($C39="OTC",ROUNDDOWN($E39*$F39*0.000909187,-1),(IF($C39="신한",ROUNDDOWN($E39*$F39*0.000036396,-1),(IF($C39="토스",$E39*$F39*0.00015,(IF($C39="US",(IF($E39*$F39*0.0025>0.01,$E39*$F39*0.0025,0.01)),IF($C39="JP",(IF($E39*$F39*0.0025>1000,$E39*$F39*0.0025,1000)),(IF($C39="R토스",0,IF($C39="무상증자(신한)",0,""))))))))))) -> 127.5 | L39: =IF($C39="OTC",ROUNDDOWN($I39*$E39*0.000909187,-1),(IF($C39="신한",ROUNDDOWN($I39*$E39*0.000036396,-1),(IF($C39="토스",$I39*$E39*0.00015,(IF($C39="US",(IF($I39*$E39*0.0025>0.01,$I39*$E39*0.0025,0.01)),(IF($C39="JP",(IF($I39*$E39*0.0025>1000,$I39*$E39*0.0025,1000)),(IF($C39="R토스",$I39*$E39*0.00015,(IF($C39="무상증자(신한)",ROUNDDOWN($I39*$E39*0.000036396,-1),""))))))))))))) -> 136.2 | M39: =Q39*0.0015 -> 1362 | O39: =J39-G39+1 -> 6 | P39: =$E39*$F39*$D39 -> 850000 | Q39: =$E39*$I39*$D39 -> 908000 | R39: =($N39-$K39-$L39-$M39)*$D39 -> -1625.7 | S39: =IF(Q39=0,0,Q39-P39+R39) -> 56374.3 | T39: =S39/P39 -> 0.066322706 | V39: =+P39*0.05*O39/365 -> 698.63014 | X39: =E39*I39*0.0000221 -> 20.0668 | Y39: =ROUNDUP(E39*I39*0.000021,2) -> 19.07
B40: HD현대일렉트릭 | C40: 토스 | D40: =IF(OR($C40="신한",$C40="OTC",$C40="무상증자(신한)",$C40="토스",$C40="R토스"),1,"확인") -> 1 | E40: 2 | F40: 418500 | G40: 45819 | H40: 약관 | I40: 454000 | J40: 45824 | K40: =IF($C40="OTC",ROUNDDOWN($E40*$F40*0.000909187,-1),(IF($C40="신한",ROUNDDOWN($E40*$F40*0.000036396,-1),(IF($C40="토스",$E40*$F40*0.00015,(IF($C40="US",(IF($E40*$F40*0.0025>0.01,$E40*$F40*0.0025,0.01)),IF($C40="JP",(IF($E40*$F40*0.0025>1000,$E40*$F40*0.0025,1000)),(IF($C40="R토스",0,IF($C40="무상증자(신한)",0,""))))))))))) -> 125.55 | L40: =IF($C40="OTC",ROUNDDOWN($I40*$E40*0.000909187,-1),(IF($C40="신한",ROUNDDOWN($I40*$E40*0.000036396,-1),(IF($C40="토스",$I40*$E40*0.00015,(IF($C40="US",(IF($I40*$E40*0.0025>0.01,$I40*$E40*0.0025,0.01)),(IF($C40="JP",(IF($I40*$E40*0.0025>1000,$I40*$E40*0.0025,1000)),(IF($C40="R토스",$I40*$E40*0.00015,(IF($C40="무상증자(신한)",ROUNDDOWN($I40*$E40*0.000036396,-1),""))))))))))))) -> 136.2 | M40: =Q40*0.0015 -> 1362 | O40: =J40-G40+1 -> 6 | P40: =$E40*$F40*$D40 -> 837000 | Q40: =$E40*$I40*$D40 -> 908000 | R40: =($N40-$K40-$L40-$M40)*$D40 -> -1623.75 | S40: =IF(Q40=0,0,Q40-P40+R40) -> 69376.25 | T40: =S40/P40 -> 0.082886798 | V40: =+P40*0.05*O40/365 -> 687.94521 | X40: =E40*I40*0.0000221 -> 20.0668 | Y40: =ROUNDUP(X40,2) -> 20.07
...

Sheet ING
E1: 45820 | F1: =SUMIFS(P8:P82,G8:G82,E1,H8:H82,"약관") -> 0 | H1: =SUMIF(H4:H891,"약관",P4:P891) -> 27436650 | K1: 토스증권 매수/매도 수수료 0.015% / 거래세 24년 0.18% 25년 0.15%
K2: 신한 매수 매도 수수료는 0.003639% (K-OTC는 0.0909187%, ETF 등 0.0042087%)/ 매도시 거래세는 0.15% /일본주식 거래수수료 0.25% 최소 1,000엔 /미국주식 거래수수료 0.25% 최소 $0.01 +매도 시 SEC Fee 매도액x $0.000013
B3: 종목명 | C3: 거래 유형 | D3: 적용환율 | E3: 수량 | F3: 매수단가 | G3: 매수일자 | H3: 비고 | I3: 매도단가 | J3: 매도일자 | K3: 매수수수료 | L3: 매도수수료 | M3: 매도제세금 | N3: 배당금 | O3: 보유일수 | P3: 매수총액 | Q3: 매도총액 | R3: 기타금액 | S3: 거래손익 | T3: 수익률
K4: =IF($C4="OTC",ROUNDDOWN($E4*$F4*0.000909187,-1),(IF($C4="신한",ROUNDDOWN($E4*$F4*0.000036396,-1),(IF($C4="토스",$E4*$F4*0.00015,(IF($C4="US",(IF($E4*$F4*0.0025>0.01,$E4*$F4*0.0025,0.01)),IF($C4="JP",(IF($E4*$F4*0.0025>1000,$E4*$F4*0.0025,1000)),(IF($C4="R토스",0,IF($C4="무상증자(신한)",0,""))))))))))) | L4: =IF($C4="OTC",ROUNDDOWN($I4*$E4*0.000909187,-1),(IF($C4="신한",ROUNDDOWN($I4*$E4*0.000036396,-1),(IF($C4="토스",$I4*$E4*0.00015,(IF($C4="US",(IF($I4*$E4*0.0025>0.01,$I4*$E4*0.0025,0.01)),(IF($C4="JP",(IF($I4*$E4*0.0025>1000,$I4*$E4*0.0025,1000)),(IF($C4="R토스",$I4*$E4*0.00015,(IF($C4="무상증자(신한)",ROUNDDOWN($I4*$E4*0.000036396,-1),""))))))))))))) | M4: =Q4*0.002 -> 0 | N4: =236*E4 -> 0 | P4: =$E4*$F4*$D4 -> 0 | Q4: =$E4*$I4*$D4 -> 0 | R4: =($N4-$K4-$L4-$M4)*$D4 -> #VALUE! | S4: =IF(Q4=0,0,Q4-P4+R4) -> 0 | T4: =S4/P4 -> #DIV/0!
B5: Archer Aviation | C5: US | H5: 손절만회용(15만원)/매도11달러 | P5: =$E5*$F5*$D5 -> 0 | Q5: =$E5*$I5*$D5 -> 0 | R5: =($N5-$K5-$L5-$M5)*$D5 -> 0 | S5: =IF(Q5=0,0,Q5-P5+R5) -> 0 | T5: =S5/P5 -> #DIV/0!
B6: Cassava Science | C6: US | H6: 손절만회용(131만원)/매도3.7달러 | P6: =$E6*$F6*$D6 -> 0 | Q6: =$E6*$I6*$D6 -> 0 | R6: =($N6-$K6-$L6-$M6)*$D6 -> 0 | S6: =IF(Q6=0,0,Q6-P6+R6) -> 0 | T6: =S6/P6 -> #DIV/0!
B7: Intellia Therapeautics | C7: US | D7: =IF(OR($C7="신한",$C7="OTC",$C7="무상증자(신한)",$C7="토스",$C7="R토스"),1,"확인") -> 확인 | H7: 손절만회용(140만원)/매도18.8달러 | P7: =$E7*$F7*$D7 -> #VALUE! | Q7: =$E7*$I7*$D7 -> #VALUE! | R7: =($N7-$K7-$L7-$M7)*$D7 -> #VALUE! | S7: =IF(Q7=0,0,Q7-P7+R7) -> #VALUE! | T7: =S7/P7 -> #VALUE!
B8: LG씨엔에스 | C8: 토스 | D8: =IF(OR($C8="신한",$C8="OTC",$C8="무상증자(신한)",$C8="토스",$C8="R토스"),1,"확인") -> 1 | E8: 3 | F8: 66000 | G8: 45824 | H8: 약관 | I8: 67500 | J8: 46134 | K8: =IF($C8="OTC",ROUNDDOWN($E8*$F8*0.000909187,-1),(IF($C8="신한",ROUNDDOWN($E8*$F8*0.000036396,-1),(IF($C8="토스",$E8*$F8*0.00015,(IF($C8="US",(IF($E8*$F8*0.0025>0.01,$E8*$F8*0.0025,0.01)),IF($C8="JP",(IF($E8*$F8*0.0025>1000,$E8*$F8*0.0025,1000)),(IF($C8="R토스",0,IF($C8="무상증자(신한)",0,""))))))))))) -> 29.7 | L8: =IF($C8="OTC",ROUNDDOWN($I8*$E8*0.000909187,-1),(IF($C8="신한",ROUNDDOWN($I8*$E8*0.000036396,-1),(IF($C8="토스",$I8*$E8*0.00015,(IF($C8="US",(IF($I8*$E8*0.0025>0.01,$I8*$E8*0.0025,0.01)),(IF($C8="JP",(IF($I8*$E8*0.0025>1000,$I8*$E8*0.0025,1000)),(IF($C8="R토스",$I8*$E8*0.00015,(IF($C8="무상증자(신한)",ROUNDDOWN($I8*$E8*0.000036396,-1),""))))))))))))) -> 30.375 | M8: =Q8*0.002 -> 405 | N8: =750*E8+1100*E8*(1-0.154) -> 5041.8 | O8: =J8-G8+1 -> 311 | P8: =$E8*$F8*$D8 -> 198000 | Q8: =$E8*$I8*$D8 -> 202500 | R8: =($N8-$K8-$L8-$M8)*$D8 -> 4576.725 | S8: =IF(Q8=0,0,Q8-P8+R8) -> 9076.725 | T8: =S8/P8 -> 0.045842045 | U8: =IF(O8<0,0,P8*0.05*O8/365) -> 8435.3425
B9: LG씨엔에스 | C9: R토스 | D9: =IF(OR($C9="신한",$C9="OTC",$C9="무상증자(신한)",$C9="토스",$C9="R토스"),1,"확인") -> 1 | E9: 1 | F9: 65000 | G9: 46008 | I9: 67500 | J9: 46134 | K9: =IF($C9="OTC",ROUNDDOWN($E9*$F9*0.000909187,-1),(IF($C9="신한",ROUNDDOWN($E9*$F9*0.000036396,-1),(IF($C9="토스",$E9*$F9*0.00015,(IF($C9="US",(IF($E9*$F9*0.0025>0.01,$E9*$F9*0.0025,0.01)),IF($C9="JP",(IF($E9*$F9*0.0025>1000,$E9*$F9*0.0025,1000)),(IF($C9="R토스",0,IF($C9="무상증자(신한)",0,""))))))))))) -> 0 | L9: =IF($C9="OTC",ROUNDDOWN($I9*$E9*0.000909187,-1),(IF($C9="신한",ROUNDDOWN($I9*$E9*0.000036396,-1),(IF($C9="토스",$I9*$E9*0.00015,(IF($C9="US",(IF($I9*$E9*0.0025>0.01,$I9*$E9*0.0025,0.01)),(IF($C9="JP",(IF($I9*$E9*0.0025>1000,$I9*$E9*0.0025,1000)),(IF($C9="R토스",$I9*$E9*0.00015,(IF($C9="무상증자(신한)",ROUNDDOWN($I9*$E9*0.000036396,-1),""))))))))))))) -> 10.125 | M9: =Q9*0.002 -> 135 | N9: =E9*1100*(1-0.154) -> 930.6 | O9: =J9-G9+1 -> 127 | P9: =$E9*$F9*$D9 -> 65000 | Q9: =$E9*$I9*$D9 -> 67500 | R9: =($N9-$K9-$L9-$M9)*$D9 -> 785.475 | S9: =IF(Q9=0,0,Q9-P9+R9) -> 3285.475 | T9: =S9/P9 -> 0.050545769 | U9: =IF(O9<0,0,P9*0.05*O9/365) -> 1130.8219
B10: LG씨엔에스 | C10: R토스 | D10: =IF(OR($C10="신한",$C10="OTC",$C10="무상증자(신한)",$C10="토스",$C10="R토스"),1,"확인") -> 1 | E10: 1 | F10: 63000 | G10: 46015 | I10: 67500 | J10: 46134 | K10: =IF($C10="OTC",ROUNDDOWN($E10*$F10*0.000909187,-1),(IF($C10="신한",ROUNDDOWN($E10*$F10*0.000036396,-1),(IF($C10="토스",$E10*$F10*0.00015,(IF($C10="US",(IF($E10*$F10*0.0025>0.01,$E10*$F10*0.0025,0.01)),IF($C10="JP",(IF($E10*$F10*0.0025>1000,$E10*$F10*0.0025,1000)),(IF($C10="R토스",0,IF($C10="무상증자(신한)",0,""))))))))))) -> 0 | L10: =IF($C10="OTC",ROUNDDOWN($I10*$E10*0.000909187,-1),(IF($C10="신한",ROUNDDOWN($I10*$E10*0.000036396,-1),(IF($C10="토스",$I10*$E10*0.00015,(IF($C10="US",(IF($I10*$E10*0.0025>0.01,$I10*$E10*0.0025,0.01)),(IF($C10="JP",(IF($I10*$E10*0.0025>1000,$I10*$E10*0.0025,1000)),(IF($C10="R토스",$I10*$E10*0.00015,(IF($C10="무상증자(신한)",ROUNDDOWN($I10*$E10*0.000036396,-1),""))))))))))))) -> 10.125 | M10: =Q10*0.002 -> 135 | N10: =E10*1100*(1-0.154) -> 930.6 | O10: =J10-G10+1 -> 120 | P10: =$E10*$F10*$D10 -> 63000 | Q10: =$E10*$I10*$D10 -> 67500 | R10: =($N10-$K10-$L10-$M10)*$D10 -> 785.475 | S10: =IF(Q10=0,0,Q10-P10+R10) -> 5285.475 | T10: =S10/P10 -> 0.083896429 | U10: =IF(O10<0,0,P10*0.05*O10/365) -> 1035.6164
B11: LG씨엔에스 | C11: R토스 | D11: =IF(OR($C11="신한",$C11="OTC",$C11="무상증자(신한)",$C11="토스",$C11="R토스"),1,"확인") -> 1 | E11: 1 | F11: 60900 | G11: 46024 | I11: 67500 | J11: 46134 | K11: =IF($C11="OTC",ROUNDDOWN($E11*$F11*0.000909187,-1),(IF($C11="신한",ROUNDDOWN($E11*$F11*0.000036396,-1),(IF($C11="토스",$E11*$F11*0.00015,(IF($C11="US",(IF($E11*$F11*0.0025>0.01,$E11*$F11*0.0025,0.01)),IF($C11="JP",(IF($E11*$F11*0.0025>1000,$E11*$F11*0.0025,1000)),(IF($C11="R토스",0,IF($C11="무상증자(신한)",0,""))))))))))) -> 0 | L11: =IF($C11="OTC",ROUNDDOWN($I11*$E11*0.000909187,-1),(IF($C11="신한",ROUNDDOWN($I11*$E11*0.000036396,-1),(IF($C11="토스",$I11*$E11*0.00015,(IF($C11="US",(IF($I11*$E11*0.0025>0.01,$I11*$E11*0.0025,0.01)),(IF($C11="JP",(IF($I11*$E11*0.0025>1000,$I11*$E11*0.0025,1000)),(IF($C11="R토스",$I11*$E11*0.00015,(IF($C11="무상증자(신한)",ROUNDDOWN($I11*$E11*0.000036396,-1),""))))))))))))) -> 10.125 | M11: =Q11*0.002 -> 135 | N11: =E11*1100*(1-0.154) -> 930.6 | O11: =J11-G11+1 -> 111 | P11: =$E11*$F11*$D11 -> 60900 | Q11: =$E11*$I11*$D11 -> 67500 | R11: =($N11-$K11-$L11-$M11)*$D11 -> 785.475 | S11: =IF(Q11=0,0,Q11-P11+R11) -> 7385.475 | T11: =S11/P11 -> 0.12127217 | U11: =IF(O11<0,0,P11*0.05*O11/365) -> 926.0137
B12: LG씨엔에스 | C12: R토스 | D12: =IF(OR($C12="신한",$C12="OTC",$C12="무상증자(신한)",$C12="토스",$C12="R토스"),1,"확인") -> 1 | E12: 1 | F12: 62000 | G12: 46029 | I12: 67500 | J12: 46134 | K12: =IF($C12="OTC",ROUNDDOWN($E12*$F12*0.000909187,-1),(IF($C12="신한",ROUNDDOWN($E12*$F12*0.000036396,-1),(IF($C12="토스",$E12*$F12*0.00015,(IF($C12="US",(IF($E12*$F12*0.0025>0.01,$E12*$F12*0.0025,0.01)),IF($C12="JP",(IF($E12*$F12*0.0025>1000,$E12*$F12*0.0025,1000)),(IF($C12="R토스",0,IF($C12="무상증자(신한)",0,""))))))))))) -> 0 | L12: =IF($C12="OTC",ROUNDDOWN($I12*$E12*0.000909187,-1),(IF($C12="신한",ROUNDDOWN($I12*$E12*0.000036396,-1),(IF($C12="토스",$I12*$E12*0.00015,(IF($C12="US",(IF($I12*$E12*0.0025>0.01,$I12*$E12*0.0025,0.01)),(IF($C12="JP",(IF($I12*$E12*0.0025>1000,$I12*$E12*0.0025,1000)),(IF($C12="R토스",$I12*$E12*0.00015,(IF($C12="무상증자(신한)",ROUNDDOWN($I12*$E12*0.000036396,-1),""))))))))))))) -> 10.125 | M12: =Q12*0.002 -> 135 | N12: =E12*1100*(1-0.154) -> 930.6 | O12: =J12-G12+1 -> 106 | P12: =$E12*$F12*$D12 -> 62000 | Q12: =$E12*$I12*$D12 -> 67500 | R12: =($N12-$K12-$L12-$M12)*$D12 -> 785.475 | S12: =IF(Q12=0,0,Q12-P12+R12) -> 6285.475 | T12: =S12/P12 -> 0.10137863 | U12: =IF(O12<0,0,P12*0.05*O12/365) -> 900.27397
B13: LG씨엔에스 | C13: R토스 | D13: =IF(OR($C13="신한",$C13="OTC",$C13="무상증자(신한)",$C13="토스",$C13="R토스"),1,"확인") -> 1 | E13: 1 | F13: 62100 | G13: 46036 | I13: 67500 | J13: 46134 | K13: =IF($C13="OTC",ROUNDDOWN($E13*$F13*0.000909187,-1),(IF($C13="신한",ROUNDDOWN($E13*$F13*0.000036396,-1),(IF($C13="토스",$E13*$F13*0.00015,(IF($C13="US",(IF($E13*$F13*0.0025>0.01,$E13*$F13*0.0025,0.01)),IF($C13="JP",(IF($E13*$F13*0.0025>1000,$E13*$F13*0.0025,1000)),(IF($C13="R토스",0,IF($C13="무상증자(신한)",0,""))))))))))) -> 0 | L13: =IF($C13="OTC",ROUNDDOWN($I13*$E13*0.000909187,-1),(IF($C13="신한",ROUNDDOWN($I13*$E13*0.000036396,-1),(IF($C13="토스",$I13*$E13*0.00015,(IF($C13="US",(IF($I13*$E13*0.0025>0.01,$I13*$E13*0.0025,0.01)),(IF($C13="JP",(IF($I13*$E13*0.0025>1000,$I13*$E13*0.0025,1000)),(IF($C13="R토스",$I13*$E13*0.00015,(IF($C13="무상증자(신한)",ROUNDDOWN($I13*$E13*0.000036396,-1),""))))))))))))) -> 10.125 | M13: =Q13*0.002 -> 135 | N13: =E13*1100*(1-0.154) -> 930.6 | O13: =J13-G13+1 -> 99 | P13: =$E13*$F13*$D13 -> 62100 | Q13: =$E13*$I13*$D13 -> 67500 | R13: =($N13-$K13-$L13-$M13)*$D13 -> 785.475 | S13: =IF(Q13=0,0,Q13-P13+R13) -> 6185.475 | T13: =S13/P13 -> 0.099605072 | U13: =IF(O13<0,0,P13*0.05*O13/365) -> 842.17808
B14: LG씨엔에스 | C14: R토스 | D14: =IF(OR($C14="신한",$C14="OTC",$C14="무상증자(신한)",$C14="토스",$C14="R토스"),1,"확인") -> 1 | E14: 1 | F14: 68900 | G14: 46043 | I14: 67500 | J14: 46134 | K14: =IF($C14="OTC",ROUNDDOWN($E14*$F14*0.000909187,-1),(IF($C14="신한",ROUNDDOWN($E14*$F14*0.000036396,-1),(IF($C14="토스",$E14*$F14*0.00015,(IF($C14="US",(IF($E14*$F14*0.0025>0.01,$E14*$F14*0.0025,0.01)),IF($C14="JP",(IF($E14*$F14*0.0025>1000,$E14*$F14*0.0025,1000)),(IF($C14="R토스",0,IF($C14="무상증자(신한)",0,""))))))))))) -> 0 | L14: =IF($C14="OTC",ROUNDDOWN($I14*$E14*0.000909187,-1),(IF($C14="신한",ROUNDDOWN($I14*$E14*0.000036396,-1),(IF($C14="토스",$I14*$E14*0.00015,(IF($C14="US",(IF($I14*$E14*0.0025>0.01,$I14*$E14*0.0025,0.01)),(IF($C14="JP",(IF($I14*$E14*0.0025>1000,$I14*$E14*0.0025,1000)),(IF($C14="R토스",$I14*$E14*0.00015,(IF($C14="무상증자(신한)",ROUNDDOWN($I14*$E14*0.000036396,-1),""))))))))))))) -> 10.125 | M14: =Q14*0.002 -> 135 | N14: =E14*1100*(1-0.154) -> 930.6 | O14: =J14-G14+1 -> 92 | P14: =$E14*$F14*$D14 -> 68900 | Q14: =$E14*$I14*$D14 -> 67500 | R14: =($N14-$K14-$L14-$M14)*$D14 -> 785.475 | S14: =IF(Q14=0,0,Q14-P14+R14) -> -614.525 | T14: =S14/P14 -> -0.0089190856 | U14: =IF(O14<0,0,P14*0.05*O14/365) -> 868.32877
B15: LG씨엔에스 | C15: R토스 | D15: =IF(OR($C15="신한",$C15="OTC",$C15="무상증자(신한)",$C15="토스",$C15="R토스"),1,"확인") -> 1 | E15: 1 | F15: 69300 | G15: 46050 | I15: 67500 | J15: 46134 | K15: =IF($C15="OTC",ROUNDDOWN($E15*$F15*0.000909187,-1),(IF($C15="신한",ROUNDDOWN($E15*$F15*0.000036396,-1),(IF($C15="토스",$E15*$F15*0.00015,(IF($C15="US",(IF($E15*$F15*0.0025>0.01,$E15*$F15*0.0025,0.01)),IF($C15="JP",(IF($E15*$F15*0.0025>1000,$E15*$F15*0.0025,1000)),(IF($C15="R토스",0,IF($C15="무상증자(신한)",0,""))))))))))) -> 0 | L15: =IF($C15="OTC",ROUNDDOWN($I15*$E15*0.000909187,-1),(IF($C15="신한",ROUNDDOWN($I15*$E15*0.000036396,-1),(IF($C15="토스",$I15*$E15*0.00015,(IF($C15="US",(IF($I15*$E15*0.0025>0.01,$I15*$E15*0.0025,0.01)),(IF($C15="JP",(IF($I15*$E15*0.0025>1000,$I15*$E15*0.0025,1000)),(IF($C15="R토스",$I15*$E15*0.00015,(IF($C15="무상증자(신한)",ROUNDDOWN($I15*$E15*0.000036396,-1),""))))))))))))) -> 10.125 | M15: =Q15*0.002 -> 135 | N15: =E15*1100*(1-0.154) -> 930.6 | O15: =J15-G15+1 -> 85 | P15: =$E15*$F15*$D15 -> 69300 | Q15: =$E15*$I15*$D15 -> 67500 | R15: =($N15-$K15-$L15-$M15)*$D15 -> 785.475 | S15: =IF(Q15=0,0,Q15-P15+R15) -> -1014.525 | T15: =S15/P15 -> -0.01463961 | U15: =IF(O15<0,0,P15*0.05*O15/365) -> 806.91781
B16: LG씨엔에스 | C16: R토스 | D16: =IF(OR($C16="신한",$C16="OTC",$C16="무상증자(신한)",$C16="토스",$C16="R토스"),1,"확인") -> 1 | E16: 1 | F16: 70400 | G16: 46057 | I16: 67500 | J16: 46134 | K16: =IF($C16="OTC",ROUNDDOWN($E16*$F16*0.000909187,-1),(IF($C16="신한",ROUNDDOWN($E16*$F16*0.000036396,-1),(IF($C16="토스",$E16*$F16*0.00015,(IF($C16="US",(IF($E16*$F16*0.0025>0.01,$E16*$F16*0.0025,0.01)),IF($C16="JP",(IF($E16*$F16*0.0025>1000,$E16*$F16*0.0025,1000)),(IF($C16="R토스",0,IF($C16="무상증자(신한)",0,""))))))))))) -> 0 | L16: =IF($C16="OTC",ROUNDDOWN($I16*$E16*0.000909187,-1),(IF($C16="신한",ROUNDDOWN($I16*$E16*0.000036396,-1),(IF($C16="토스",$I16*$E16*0.00015,(IF($C16="US",(IF($I16*$E16*0.0025>0.01,$I16*$E16*0.0025,0.01)),(IF($C16="JP",(IF($I16*$E16*0.0025>1000,$I16*$E16*0.0025,1000)),(IF($C16="R토스",$I16*$E16*0.00015,(IF($C16="무상증자(신한)",ROUNDDOWN($I16*$E16*0.000036396,-1),""))))))))))))) -> 10.125 | M16: =Q16*0.002 -> 135 | N16: =E16*1100*(1-0.154) -> 930.6 | O16: =J16-G16+1 -> 78 | P16: =$E16*$F16*$D16 -> 70400 | Q16: =$E16*$I16*$D16 -> 67500 | R16: =($N16-$K16-$L16-$M16)*$D16 -> 785.475 | S16: =IF(Q16=0,0,Q16-P16+R16) -> -2114.525 | T16: =S16/P16 -> -0.030035866 | U16: =IF(O16<0,0,P16*0.05*O16/365) -> 752.21918
B17: LG씨엔에스 | C17: R토스 | D17: =IF(OR($C17="신한",$C17="OTC",$C17="무상증자(신한)",$C17="토스",$C17="R토스"),1,"확인") -> 1 | E17: 1 | F17: 68400 | G17: 46064 | I17: 67500 | J17: 46134 | K17: =IF($C17="OTC",ROUNDDOWN($E17*$F17*0.000909187,-1),(IF($C17="신한",ROUNDDOWN($E17*$F17*0.000036396,-1),(IF($C17="토스",$E17*$F17*0.00015,(IF($C17="US",(IF($E17*$F17*0.0025>0.01,$E17*$F17*0.0025,0.01)),IF($C17="JP",(IF($E17*$F17*0.0025>1000,$E17*$F17*0.0025,1000)),(IF($C17="R토스",0,IF($C17="무상증자(신한)",0,""))))))))))) -> 0 | L17: =IF($C17="OTC",ROUNDDOWN($I17*$E17*0.000909187,-1),(IF($C17="신한",ROUNDDOWN($I17*$E17*0.000036396,-1),(IF($C17="토스",$I17*$E17*0.00015,(IF($C17="US",(IF($I17*$E17*0.0025>0.01,$I17*$E17*0.0025,0.01)),(IF($C17="JP",(IF($I17*$E17*0.0025>1000,$I17*$E17*0.0025,1000)),(IF($C17="R토스",$I17*$E17*0.00015,(IF($C17="무상증자(신한)",ROUNDDOWN($I17*$E17*0.000036396,-1),""))))))))))))) -> 10.125 | M17: =Q17*0.002 -> 135 | N17: =E17*1100*(1-0.154) -> 930.6 | O17: =J17-G17+1 -> 71 | P17: =$E17*$F17*$D17 -> 68400 | Q17: =$E17*$I17*$D17 -> 67500 | R17: =($N17-$K17-$L17-$M17)*$D17 -> 785.475 | S17: =IF(Q17=0,0,Q17-P17+R17) -> -114.525 | T17: =S17/P17 -> -0.0016743421 | U17: =IF(O17<0,0,P17*0.05*O17/365) -> 665.26027
B18: LG씨엔에스 | C18: R토스 | D18: =IF(OR($C18="신한",$C18="OTC",$C18="무상증자(신한)",$C18="토스",$C18="R토스"),1,"확인") -> 1 | E18: 1 | F18: 70900 | G18: 46072 | I18: 67500 | J18: 46134 | K18: =IF($C18="OTC",ROUNDDOWN($E18*$F18*0.000909187,-1),(IF($C18="신한",ROUNDDOWN($E18*$F18*0.000036396,-1),(IF($C18="토스",$E18*$F18*0.00015,(IF($C18="US",(IF($E18*$F18*0.0025>0.01,$E18*$F18*0.0025,0.01)),IF($C18="JP",(IF($E18*$F18*0.0025>1000,$E18*$F18*0.0025,1000)),(IF($C18="R토스",0,IF($C18="무상증자(신한)",0,""))))))))))) -> 0 | L18: =IF($C18="OTC",ROUNDDOWN($I18*$E18*0.000909187,-1),(IF($C18="신한",ROUNDDOWN($I18*$E18*0.000036396,-1),(IF($C18="토스",$I18*$E18*0.00015,(IF($C18="US",(IF($I18*$E18*0.0025>0.01,$I18*$E18*0.0025,0.01)),(IF($C18="JP",(IF($I18*$E18*0.0025>1000,$I18*$E18*0.0025,1000)),(IF($C18="R토스",$I18*$E18*0.00015,(IF($C18="무상증자(신한)",ROUNDDOWN($I18*$E18*0.000036396,-1),""))))))))))))) -> 10.125 | M18: =Q18*0.002 -> 135 | N18: =E18*1100*(1-0.154) -> 930.6 | O18: =J18-G18+1 -> 63 | P18: =$E18*$F18*$D18 -> 70900 | Q18: =$E18*$I18*$D18 -> 67500 | R18: =($N18-$K18-$L18-$M18)*$D18 -> 785.475 | S18: =IF(Q18=0,0,Q18-P18+R18) -> -2614.525 | T18: =S18/P18 -> -0.036876234 | U18: =IF(O18<0,0,P18*0.05*O18/365) -> 611.87671
B19: LG씨엔에스 | C19: R토스 | D19: =IF(OR($C19="신한",$C19="OTC",$C19="무상증자(신한)",$C19="토스",$C19="R토스"),1,"확인") -> 1 | E19: 1 | F19: 69900 | G19: 46078 | I19: 67500 | J19: 46134 | K19: =IF($C19="OTC",ROUNDDOWN($E19*$F19*0.000909187,-1),(IF($C19="신한",ROUNDDOWN($E19*$F19*0.000036396,-1),(IF($C19="토스",$E19*$F19*0.00015,(IF($C19="US",(IF($E19*$F19*0.0025>0.01,$E19*$F19*0.0025,0.01)),IF($C19="JP",(IF($E19*$F19*0.0025>1000,$E19*$F19*0.0025,1000)),(IF($C19="R토스",0,IF($C19="무상증자(신한)",0,""))))))))))) -> 0 | L19: =IF($C19="OTC",ROUNDDOWN($I19*$E19*0.000909187,-1),(IF($C19="신한",ROUNDDOWN($I19*$E19*0.000036396,-1),(IF($C19="토스",$I19*$E19*0.00015,(IF($C19="US",(IF($I19*$E19*0.0025>0.01,$I19*$E19*0.0025,0.01)),(IF($C19="JP",(IF($I19*$E19*0.0025>1000,$I19*$E19*0.0025,1000)),(IF($C19="R토스",$I19*$E19*0.00015,(IF($C19="무상증자(신한)",ROUNDDOWN($I19*$E19*0.000036396,-1),""))))))))))))) -> 10.125 | M19: =Q19*0.002 -> 135 | N19: =E19*1100*(1-0.154) -> 930.6 | O19: =J19-G19+1 -> 57 | P19: =$E19*$F19*$D19 -> 69900 | Q19: =$E19*$I19*$D19 -> 67500 | R19: =($N19-$K19-$L19-$M19)*$D19 -> 785.475 | S19: =IF(Q19=0,0,Q19-P19+R19) -> -1614.525 | T19: =S19/P19 -> -0.023097639 | U19: =IF(O19<0,0,P19*0.05*O19/365) -> 545.79452
B20: LG씨엔에스 | C20: R토스 | D20: =IF(OR($C20="신한",$C20="OTC",$C20="무상증자(신한)",$C20="토스",$C20="R토스"),1,"확인") -> 1 | E20: 1 | F20: 64100 | G20: 46085 | I20: 67500 | J20: 46134 | K20: =IF($C20="OTC",ROUNDDOWN($E20*$F20*0.000909187,-1),(IF($C20="신한",ROUNDDOWN($E20*$F20*0.000036396,-1),(IF($C20="토스",$E20*$F20*0.00015,(IF($C20="US",(IF($E20*$F20*0.0025>0.01,$E20*$F20*0.0025,0.01)),IF($C20="JP",(IF($E20*$F20*0.0025>1000,$E20*$F20*0.0025,1000)),(IF($C20="R토스",0,IF($C20="무상증자(신한)",0,""))))))))))) -> 0 | L20: =IF($C20="OTC",ROUNDDOWN($I20*$E20*0.000909187,-1),(IF($C20="신한",ROUNDDOWN($I20*$E20*0.000036396,-1),(IF($C20="토스",$I20*$E20*0.00015,(IF($C20="US",(IF($I20*$E20*0.0025>0.01,$I20*$E20*0.0025,0.01)),(IF($C20="JP",(IF($I20*$E20*0.0025>1000,$I20*$E20*0.0025,1000)),(IF($C20="R토스",$I20*$E20*0.00015,(IF($C20="무상증자(신한)",ROUNDDOWN($I20*$E20*0.000036396,-1),""))))))))))))) -> 10.125 | M20: =Q20*0.002 -> 135 | N20: =E20*1100*(1-0.154) -> 930.6 | O20: =J20-G20+1 -> 50 | P20: =$E20*$F20*$D20 -> 64100 | Q20: =$E20*$I20*$D20 -> 67500 | R20: =($N20-$K20-$L20-$M20)*$D20 -> 785.475 | S20: =IF(Q20=0,0,Q20-P20+R20) -> 4185.475 | T20: =S20/P20 -> 0.065296022 | U20: =IF(O20<0,0,P20*0.05*O20/365) -> 439.0411
... B22: LG씨엔에스 | C22: R토스 | D22: =IF(OR($C22="신한",$C22="OTC",$C22="무상증자(신한)",$C22="토스",$C22="R토스"),1,"확인") -> 1 | E22: 1 | F22: 67400 | G22: 46099 | I22: 67500 | J22: 46134 | K22: =IF($C22="OTC",ROUNDDOWN($E22*$F22*0.000909187,-1),(IF($C22="신한",ROUNDDOWN($E22*$F22*0.000036396,-1),(IF($C22="토스",$E22*$F22*0.00015,(IF($C22="US",(IF($E22*$F22*0.0025>0.01,$E22*$F22*0.0025,0.01)),IF($C22="JP",(IF($E22*$F22*0.0025>1000,$E22*$F22*0.0025,1000)),(IF($C22="R토스",0,IF($C22="무상증자(신한)",0,""))))))))))) -> 0 | L22: =IF($C22="OTC",ROUNDDOWN($I22*$E22*0.000909187,-1),(IF($C22="신한",ROUNDDOWN($I22*$E22*0.000036396,-1),(IF($C22="토스",$I22*$E22*0.00015,(IF($C22="US",(IF($I22*$E22*0.0025>0.01,$I22*$E22*0.0025,0.01)),(IF($C22="JP",(IF($I22*$E22*0.0025>1000,$I22*$E22*0.0025,1000)),(IF($C22="R토스",$I22*$E22*0.00015,(IF($C22="무상증자(신한)",ROUNDDOWN($I22*$E22*0.000036396,-1),""))))))))))))) -> 10.125 | M22: =Q22*0.002 -> 135 | N22: =E22*1100*(1-0.154) -> 930.6 | O22: =J22-G22+1 -> 36 | P22: =$E22*$F22*$D22 -> 67400 | Q22: =$E22*$I22*$D22 -> 67500 | R22: =($N22-$K22-$L22-$M22)*$D22 -> 785.475 | S22: =IF(Q22=0,0,Q22-P22+R22) -> 885.475 | T22: =S22/P22 -> 0.013137611 | U22: =IF(O22<0,0,P22*0.05*O22/365) -> 332.38356
B23: Plugpower | C23: US | D23: =IF(OR($C23="신한",$C23="OTC",$C23="무상증자(신한)",$C23="토스",$C23="R토스"),1,"확인") -> 확인 | H23: 손절만회용(90만원)/매도 3.7달러 | P23: =$E23*$F23*$D23 -> #VALUE! | Q23: =$E23*$I23*$D23 -> #VALUE! | R23: =($N23-$K23-$L23-$M23)*$D23 -> #VALUE! | S23: =IF(Q23=0,0,Q23-P23+R23) -> #VALUE! | T23: =S23/P23 -> #VALUE!
B24: S&P BIO | C24: US | D24: =IF(OR($C24="신한",$C24="OTC",$C24="무상증자(신한)",$C24="토스",$C24="R토스"),1,"확인") -> 확인 | H24: 손절만회용(55만원)/매도103.5달러 | P24: =$E24*$F24*$D24 -> #VALUE! | Q24: =$E24*$I24*$D24 -> #VALUE! | R24: =($N24-$K24-$L24-$M24)*$D24 -> #VALUE! | S24: =IF(Q24=0,0,Q24-P24+R24) -> #VALUE! | T24: =S24/P24 -> #VALUE!
B25: SK하이닉스 | C25: 신한 | D25: =IF(OR($C25="신한",$C25="OTC",$C25="무상증자(신한)",$C25="토스",$C25="R토스"),1,"확인") -> 1 | E25: 6 | F25: 805000 | G25: 46112 | I25: 1025000 | J25: 46122 | K25: =IF($C25="OTC",ROUNDDOWN($E25*$F25*0.000909187,-1),(IF($C25="신한",ROUNDDOWN($E25*$F25*0.000036396,-1),(IF($C25="토스",$E25*$F25*0.00015,(IF($C25="US",(IF($E25*$F25*0.0025>0.01,$E25*$F25*0.0025,0.01)),IF($C25="JP",(IF($E25*$F25*0.0025>1000,$E25*$F25*0.0025,1000)),(IF($C25="R토스",0,IF($C25="무상증자(신한)",0,""))))))))))) -> 170 | L25: =IF($C25="OTC",ROUNDDOWN($I25*$E25*0.000909187,-1),(IF($C25="신한",ROUNDDOWN($I25*$E25*0.000036396,-1),(IF($C25="토스",$I25*$E25*0.00015,(IF($C25="US",(IF($I25*$E25*0.0025>0.01,$I25*$E25*0.0025,0.01)),(IF($C25="JP",(IF($I25*$E25*0.0025>1000,$I25*$E25*0.0025,1000)),(IF($C25="R토스",$I25*$E25*0.00015,(IF($C25="무상증자(신한)",ROUNDDOWN($I25*$E25*0.000036396,-1),""))))))))))))) -> 220 | M25: =Q25*0.002 -> 12300 | O25: =J25-G25+1 -> 11 | P25: =$E25*$F25*$D25 -> 4830000 | Q25: =$E25*$I25*$D25 -> 6150000 | R25: =($N25-$K25-$L25-$M25)*$D25 -> -12690 | S25: =IF(Q25=0,0,Q25-P25+R25) -> 1307310 | T25: =S25/P25 -> 0.2706646 | U25: =IF(O25<0,0,P25*0.05*O25/365) -> 7278.0822
B26: SK하이닉스 | C26: 토스 | D26: =IF(OR($C26="신한",$C26="OTC",$C26="무상증자(신한)",$C26="토스",$C26="R토스"),1,"확인") -> 1 | E26: 8 | F26: 1240000 | G26: 46139 | I26: 1243000 | J26: 46134 | K26: 0 | L26: 0 | M26: =Q26*0.002 -> 19888 | O26: =J26-G26+1 -> -4 | P26: =$E26*$F26*$D26 -> 9920000 | Q26: =$E26*$I26*$D26 -> 9944000 | R26: =($N26-$K26-$L26-$M26)*$D26 -> -19888 | S26: =IF(Q26=0,0,Q26-P26+R26) -> 4112 | T26: =S26/P26 -> 0.00041451613 | U26: =IF(O26<0,0,P26*0.05*O26/365) -> 0
B27: SK하이닉스 | C27: 토스 | D27: =IF(OR($C27="신한",$C27="OTC",$C27="무상증자(신한)",$C27="토스",$C27="R토스"),1,"확인") -> 1 | E27: 80 | F27: 1239000 | G27: 46139 | I27: 1243000 | J27: 46134 | K27: 0 | L27: 0 | M27: =Q27*0.002 -> 198880 | O27: =J27-G27+1 -> -4 | P27: =$E27*$F27*$D27 -> 99120000 | Q27: =$E27*$I27*$D27 -> 99440000 | R27: =($N27-$K27-$L27-$M27)*$D27 -> -198880 | S27: =IF(Q27=0,0,Q27-P27+R27) -> 121120 | T27: =S27/P27 -> 0.0012219532 | U27: =IF(O27<0,0,P27*0.05*O27/365) -> 0
B28: Tiger 레버리지 | C28: 신한 | D28: =IF(OR($C28="신한",$C28="OTC",$C28="무상증자(신한)",$C28="토스",$C28="R토스"),1,"확인") -> 1 | E28: 23 | F28: 88005 | G28: 46086 | I28: 95000 | J28: 46126 | K28: =IF($C28="OTC",ROUNDDOWN($E28*$F28*0.000909187,-1),(IF($C28="신한",ROUNDDOWN($E28*$F28*0.000036396,-1),(IF($C28="토스",$E28*$F28*0.00015,(IF($C28="US",(IF($E28*$F28*0.0025>0.01,$E28*$F28*0.0025,0.01)),IF($C28="JP",(IF($E28*$F28*0.0025>1000,$E28*$F28*0.0025,1000)),(IF($C28="R토스",0,IF($C28="무상증자(신한)",0,""))))))))))) -> 70 | L28: =IF($C28="OTC",ROUNDDOWN($I28*$E28*0.000909187,-1),(IF($C28="신한",ROUNDDOWN($I28*$E28*0.000036396,-1),(IF($C28="토스",$I28*$E28*0.00015,(IF($C28="US",(IF($I28*$E28*0.0025>0.01,$I28*$E28*0.0025,0.01)),(IF($C28="JP",(IF($I28*$E28*0.0025>1000,$I28*$E28*0.0025,1000)),(IF($C28="R토스",$I28*$E28*0.00015,(IF($C28="무상증자(신한)",ROUNDDOWN($I28*$E28*0.000036396,-1),""))))))))))))) -> 70 | M28: =Q28*0.002 -> 4370 | O28: =J28-G28+1 -> 41 | P28: =$E28*$F28*$D28 -> 2024115 | Q28: =$E28*$I28*$D28 -> 2185000 | R28: =($N28-$K28-$L28-$M28)*$D28 -> -4510 | S28: =IF(Q28=0,0,Q28-P28+R28) -> 156375 | T28: =S28/P28 -> 0.077255986
B29: Tiger 레버리지 | C29: 신한 | D29: =IF(OR($C29="신한",$C29="OTC",$C29="무상증자(신한)",$C29="토스",$C29="R토스"),1,"확인") -> 1 | E29: 13 | F29: 78498 | G29: 46104 | I29: 95000 | J29: 46126 | K29: =IF($C29="OTC",ROUNDDOWN($E29*$F29*0.000909187,-1),(IF($C29="신한",ROUNDDOWN($E29*$F29*0.000036396,-1),(IF($C29="토스",$E29*$F29*0.00015,(IF($C29="US",(IF($E29*$F29*0.0025>0.01,$E29*$F29*0.0025,0.01)),IF($C29="JP",(IF($E29*$F29*0.0025>1000,$E29*$F29*0.0025,1000)),(IF($C29="R토스",0,IF($C29="무상증자(신한)",0,""))))))))))) -> 30 | L29: =IF($C29="OTC",ROUNDDOWN($I29*$E29*0.000909187,-1),(IF($C29="신한",ROUNDDOWN($I29*$E29*0.000036396,-1),(IF($C29="토스",$I29*$E29*0.00015,(IF($C29="US",(IF($I29*$E29*0.0025>0.01,$I29*$E29*0.0025,0.01)),(IF($C29="JP",(IF($I29*$E29*0.0025>1000,$I29*$E29*0.0025,1000)),(IF($C29="R토스",$I29*$E29*0.00015,(IF($C29="무상증자(신한)",ROUNDDOWN($I29*$E29*0.000036396,-1),""))))))))))))) -> 40 | M29: =Q29*0.002 -> 2470 | O29: =J29-G29+1 -> 23 | P29: =$E29*$F29*$D29 -> 1020474 | Q29: =$E29*$I29*$D29 -> 1235000 | R29: =($N29-$K29-$L29-$M29)*$D29 -> -2540 | S29: =IF(Q29=0,0,Q29-P29+R29) -> 211986 | T29: =S29/P29 -> 0.20773288
