Workbook

Sheet DCF
D3: CMTX(388210.KQ)
I5: Circuit Swith : | K5: N/A | N5: Hardcode | P5: Caution
D6: DCF Valuation | I6: Current Scenario : | K6: BASE CASE | N6: Calculation | P6: Assumption
D7: Made by J.H | I7: Target Price : | K7: =+F43 -> 102000 | N7: Reference | P7: Notes
B10: PV Factor | K10: =1/(1+$F$34)^K11 -> 0.99260951 | L10: =1/(1+$F$34)^L11 -> 0.92164299 | M10: =1/(1+$F$34)^M11 -> 0.85575023 | N10: =1/(1+$F$34)^N11 -> 0.79456846 | O10: =1/(1+$F$34)^O11 -> 0.73776087 | P10: =1/(1+$F$34)^P11 -> 0.68501473 | Q10: =1/(1+$F$34)^Q11 -> 0.63603968 | R10: =1/(1+$F$34)^R11 -> 0.59056609 | ... T10: =1/(1+$F$34)^T11 -> 0.50913986
K11: 0.1 | L11: =+K11+1 -> 1.1 | M11: =+L11+1 -> 2.1 | N11: =+M11+1 -> 3.1 | O11: =+N11+1 -> 4.1 | P11: =+O11+1 -> 5.1 | Q11: =+P11+1 -> 6.1 | R11: =+Q11+1 -> 7.1 | S11: =+R11+1 -> 8.1 | T11: =+S11+1 -> 9.1
H12: Historical | K12: Forcast
B13: (KRW B, unless stated otherwise) | H13: 44926 | I13: =+DATE(YEAR(H13)+1,MONTH(H13),DAY(H13)) -> 45291 | J13: =+DATE(YEAR(I13)+1,MONTH(I13),DAY(I13)) -> 45657 | K13: =+DATE(YEAR(J13)+1,MONTH(J13),DAY(J13)) -> 46022 | L13: =+DATE(YEAR(K13)+1,MONTH(K13),DAY(K13)) -> 46387 | M13: =+DATE(YEAR(L13)+1,MONTH(L13),DAY(L13)) -> 46752 | N13: =+DATE(YEAR(M13)+1,MONTH(M13),DAY(M13)) -> 47118 | O13: =+DATE(YEAR(N13)+1,MONTH(N13),DAY(N13)) -> 47483 | P13: =+DATE(YEAR(O13)+1,MONTH(O13),DAY(O13)) -> 47848 | ... T13: =+DATE(YEAR(S13)+1,MONTH(S13),DAY(S13)) -> 49309
B14: Revenue | H14: =+Model!H15 -> 18.635704 | I14: =+Model!I15 -> 70.196781 | J14: =+Model!J15 -> 108.66591 | K14: =+Model!K15 -> 157.85652 | L14: =+Model!L15 -> 197.47131 | M14: =+Model!M15 -> 243.07046 | N14: =+Model!N15 -> 295.88766 | O14: =+Model!O15 -> 354.90822 | P14: =+O14*(1+P15) -> 413.9027 | Q14: =+P14*(1+Q15) -> 468.94334 | R14: =+Q14*(1+R15) -> 515.71329 | S14: =+R14*(1+S15) -> 550.00298 | T14: =+S14*(1+T15) -> 568.28778
B15: Growth(%) | I15: =+I14/H14-1 -> 2.7667898 | J15: =+J14/I14-1 -> 0.54801847 | K15: =+K14/J14-1 -> 0.45267743 | L15: =+L14/K14-1 -> 0.25095444 | M15: =+M14/L14-1 -> 0.23091528 | N15: =+N14/M14-1 -> 0.21729173 | O15: =+O14/N14-1 -> 0.1994695 | P15: =+($F$33-$O$15)/6+O15 -> 0.16622459 | Q15: =+($F$33-$O$15)/6+P15 -> 0.13297967 | R15: =+($F$33-$O$15)/6+Q15 -> 0.099734751 | S15: =+($F$33-$O$15)/6+R15 -> 0.066489834 | T15: =+($F$33-$O$15)/6+S15 -> 0.033244917
B16: EBIT | H16: =+Model!H21 -> 2.5479729 | I16: =+Model!I21 -> 2.8750609 | J16: =+Model!J21 -> 23.639029 | K16: =+Model!K21 -> 52.345099 | L16: =+Model!L21 -> 65.707929 | M16: =+Model!M21 -> 78.239263 | N16: =+Model!N21 -> 100.86711 | O16: =+Model!O21 -> 126.41855 | P16: =+P14*P17 -> 147.43242 | Q16: =+Q14*Q17 -> 167.03793 | R16: =+R14*R17 -> 183.69742 | S16: =+S14*S17 -> 195.91143 | T16: =+T14*T17 -> 202.42449
B17: OPM(%) | H17: =+H16/H14 -> 0.13672533 | I17: =+I16/I14 -> 0.040957162 | J17: =+J16/J14 -> 0.21753858 | K17: =+K16/K14 -> 0.33159922 | L17: =+L16/L14 -> 0.3327467 | M17: =+M16/M14 -> 0.32187895 | N17: =+N16/N14 -> 0.34089664 | O17: =+O16/O14 -> 0.35620066 | P17: =+$F$31 -> 0.35620066 | Q17: =+$F$31 -> 0.35620066 | R17: =+$F$31 -> 0.35620066 | S17: =+$F$31 -> 0.35620066 | T17: =+$F$31 -> 0.35620066
B18: (-) Tax | H18: =+Model!H27 -> 0.12309273 | I18: =+Model!I27 -> -2.7084131 | J18: =+Model!J27 -> 1.68208 | K18: =+Model!K27 -> -5.649797 | L18: =+Model!L27 -> 14.940393 | M18: =+Model!M27 -> 17.936143 | N18: =+Model!N27 -> 23.397551 | O18: =+Model!O27 -> 29.551179 | P18: =+P16*P19 -> 34.463312 | Q18: =+Q16*Q19 -> 39.046232 | R18: =+R16*R19 -> 42.940498 | S18: =+S16*S19 -> 45.795604 | T18: =+T16*T19 -> 47.318076
B19: Tax / EBIT(%) | H19: =+H18/H16 -> 0.048310063 | I19: =+I18/I16 -> -0.94203677 | J19: =+J18/J16 -> 0.071156899 | K19: =+K18/K16 -> -0.10793364 | L19: =+L18/L16 -> 0.2273758 | M19: =+M18/M16 -> 0.22924734 | N19: =+N18/N16 -> 0.23196413 | O19: =+O18/O16 -> 0.23375668 | P19: =+$F$32 -> 0.23375668 | Q19: =+$F$32 -> 0.23375668 | R19: =+$F$32 -> 0.23375668 | S19: =+$F$32 -> 0.23375668 | T19: =+$F$32 -> 0.23375668
B20: NOPLAT | H20: =+H16-H18 -> 2.4248801 | I20: =+I16-I18 -> 5.5834741 | J20: =+J16-J18 -> 21.956949 | K20: =+K16-K18 -> 57.994896 | L20: =+L16-L18 -> 50.767536 | M20: =+M16-M18 -> 60.30312 | N20: =+N16-N18 -> 77.469559 | O20: =+O16-O18 -> 96.867366 | ... T20: =+T16-T18 -> 155.10641
B21: (+) Depreciation | H21: =+Model!H69 -> 3.2162474 | I21: =+Model!I69 -> 4.7614323 | J21: =+Model!J69 -> 8.7884377 | K21: =+Model!K69 -> 10.022485 | L21: =+Model!L69 -> 10.814432 | M21: =+Model!M69 -> 14.127308 | N21: =+Model!N69 -> 14.86807 | O21: =+Model!O69 -> 15.22639 | P21: =+O21*(1+P$15) -> 17.75739 | Q21: =+P21*(1+Q$15) -> 20.118762 | R21: =+Q21*(1+R$15) -> 22.125302 | S21: =+R21*(1+S$15) -> 23.596409 | T21: =+S21*(1+T$15) -> 24.38087
B22: (+) Amortization | H22: =+Model!H70 -> 0.18909319 | I22: =+Model!I70 -> 0.2039145 | J22: =+Model!J70 -> 0.35739515 | K22: =+Model!K70 -> 0.29903506 | L22: =+Model!L70 -> 0.46657979 | M22: =+Model!M70 -> 0.65304549 | N22: =+Model!N70 -> 0.86288763 | O22: =+Model!O70 -> 1.1013416 | P22: =+O22*(1+P$15) -> 1.2844116 | Q22: =+P22*(1+Q$15) -> 1.4552122 | R22: =+Q22*(1+R$15) -> 1.6003475 | S22: =+R22*(1+S$15) -> 1.7067543 | T22: =+S22*(1+T$15) -> 1.7634952
B23: (-) CAPEX - PPE | H23: =-Model!H75 -> 22.378156 | I23: =-Model!I75 -> 42.93495 | J23: =-Model!J75 -> 24.155169 | K23: =-Model!K75 -> 17.936117 | L23: =-Model!L75 -> 43.918782 | M23: =-Model!M75 -> 21.529471 | N23: =-Model!N75 -> 18.448625 | O23: =-Model!O75 -> 18.893235 | P23: =+O23*(1+P$15) -> 22.033755 | Q23: =+P23*(1+Q$15) -> 24.963797 | R23: =+Q23*(1+R$15) -> 27.453555 | S23: =+R23*(1+S$15) -> 29.278937 | T23: =+S23*(1+T$15) -> 30.252313
B24: (-) CAPEX - IA | H24: =-Model!H76 -> 0.12171014 | I24: =-Model!I76 -> 0.44913954 | J24: =-Model!J76 -> 0.63910665 | K24: =-Model!K76 -> 0.969214 | L24: =-Model!L76 -> 1.2124426 | M24: =-Model!M76 -> 1.4924141 | N24: =-Model!N76 -> 1.8167033 | O24: =-Model!O76 -> 2.1790802 | P24: =+O24*(1+P$15) -> 2.5412969 | Q24: =+P24*(1+Q$15) -> 2.8792378 | R24: =+Q24*(1+R$15) -> 3.1663978 | S24: =+R24*(1+S$15) -> 3.3769311 | T24: =+S24*(1+T$15) -> 3.4891969
B25: (-) Increase / (Decrease) in Net Working Capital | H25: =-Model!H71 -> 20.742333 | I25: =-Model!I71 -> 12.171059 | J25: =-Model!J71 -> -3.3937576 | K25: =-Model!K71 -> -4.5638135 | L25: =-Model!L71 -> -8.0087797 | M25: =-Model!M71 -> -10.433109 | N25: =-Model!N71 -> -8.6026754 | O25: =-Model!O71 -> -9.5747933 | P25: =+O25*(1+P$15) -> -11.166359 | Q25: =+P25*(1+Q$15) -> -12.651258 | R25: =+Q25*(1+R$15) -> -13.913028 | S25: =+R25*(1+S$15) -> -14.838103 | T25: =+S25*(1+T$15) -> -15.331395
B26: Free Cash Flow to Film (FCFF) | H26: =+H20+H21+H22-H23-H24-H25 -> -37.411978 | I26: =+I20+I21+I22-I23-I24-I25 -> -45.006327 | J26: =+J20+J21+J22-J23-J24-J25 -> 9.7022639 | K26: =+K20+K21+K22-K23-K24-K25 -> 53.974899 | L26: =+L20+L21+L22-L23-L24-L25 -> 24.926103 | M26: =+M20+M21+M22-M23-M24-M25 -> 62.494698 | N26: =+N20+N21+N22-N23-N24-N25 -> 81.537864 | O26: =+O20+O21+O22-O23-O24-O25 -> 101.69758 | ... T26: =+T20+T21+T22-T23-T24-T25 -> 162.84066
B27: Present Value of FCFF | K27: =+K26*K10 -> 53.575997 | L27: =+L26*L10 -> 22.972968 | M27: =+M26*M10 -> 53.479852 | N27: =+N26*N10 -> 64.787415 | O27: =+O26*O10 -> 75.028491 | P27: =+P26*P10 -> 81.244263 | Q27: =+Q26*Q10 -> 85.467129 | R27: =+R26*R10 -> 87.271283 | ... T27: =+T26*T10 -> 82.908671
B29: Assumption | H29: Sensitivity Analysis
B30: Revenue Growth | E30: 30E-34E | F30: =+AVERAGE(P15,F33) -> 0.083112293 | J30: Terminal Growth Rate
B31: Operating Margin | E31: 30E-34E | F31: =+O17 -> 0.35620066 | I31: =+F43 -> 102000 | J31: -0.01 | K31: -0.005 | L31: 0 | M31: 0.005 | N31: 0.01
B32: Tax / EBIT | E32: 30E-34E | F32: =+O19 -> 0.23375668 | H32: WACC | I32: 0.073 | J32: 98000 | K32: 103000 | L32: 109000 | M32: 116000 | N32: 124000
B33: Terminal Growth Rate | E33: 25E- | F33: 0 | I33: 0.075 | J33: 95000 | K33: 100000 | L33: 106000 | M33: 112000 | N33: 119000
B34: WACC | E34: 25E- | F34: 0.077 | I34: 0.077 | J34: 93000 | K34: 97000 | L34: 102000 | M34: 108000 | N34: 115000
I35: 0.079 | J35: 90000 | K35: 94000 | L35: 99000 | M35: 104000 | N35: 111000
B36: DCF Valuation | I36: 0.081 | J36: 87000 | K36: 91000 | L36: 96000 | M36: 101000 | N36: 107000
B37: Enterprise Value | F37: =+F38+F39 -> 988.71596
B38: 1) PV of Explicit Cahflow | F38: =+SUM(K27:O27) -> 269.84472
B39: 2) PV of Terminal Value | F39: =+F40*O10 -> 718.87123
B40: Terminal Value | F40: =+O27*(1+F33)/(F34-F33) -> 974.39599
B41: Equity Value | F41: =+F37-F42 -> 946.58976
B42: (-) Net Debt | F42: =+Model!K48+Model!K54+Model!K49 -> 42.126203
B43: Equity Value per share | F43: =+ROUND(F41/F44*10^3,-3) -> 102000
B44: (/) Issued Shares | F44: 9.27

Sheet Trading
C5: Circuit Swith : | E5: N/A | H5: Hardcode | J5: Caution
C6: Current Scenario : | E6: BASE CASE | H6: Calculation | J6: Assumption
C7: Target Price : | E7: =+DCF!F43 -> 102000 | H7: Reference | J7: Notes
B11: Ticker
E12: P/E | F12: P/E | G12: 베타 | H12: DEBT(BV) | I12: EQUITY(MV) | J12: 세율 | K12: 언레버 베타
B13: 씨엠티엑스 | G13: =+K14*(1+(1-J13)*H13/I13) -> 0.96676794 | H13: =+Model!K45 -> 105.28015 | I13: =+peer!G2/10^9 -> 930.9779 | J13: 0.23
B14: 월덱스 | E14: 6.5 | G14: 0.98 | H14: 73.9 | I14: =+peer!G4/10^9 -> 362.4163 | J14: 0.5 | K14: =+G14/(1+(1-J14)*H14/I14) -> 0.88932885
B15: 케이엔제이 | E15: 7.8 | G15: 0.94 | H15: 68 | I15: =+peer!G6/10^9 -> 164.5206 | J15: 0.04 | K15: =+G15/(1+(1-J15)*H15/I15) -> 0.67297198
B16: 하나머티리얼즈 | E16: 15.87 | F16: 14.05 | H16: 207 | I16: =+peer!G8/10^9 -> 915.7063
B17: 티씨케이 | E17: 18.1 | F17: 15.1 | H17: 40 | I17: =+peer!G10/10^9 -> 1755.168
B18: 비씨엔씨 | E18: 21.69 | F18: 20.33 | H18: 100 | I18: =+peer!G12/10^9 -> 176.9953
C21: 부채요구수익률 | E21: 0.043 | G21: WACC | H21: =E21*H13/SUM(H13:I13)*(1-J13)+E22*I13/SUM(H13:I13) -> 0.077070431
C22: 자본요구수익률 | E22: =G13*E24+E23 -> 0.08204172
C23: 무위험 금리 | E23: 0.0338
C24: MRP | E24: 0.0499

Sheet Model
D3: CMTX(388210.KQ)
I5: Circuit Swith : | K5: N/A | N5: Hardcode | P5: Caution
D6: Financial Modeling | I6: Current Scenario : | K6: BASE CASE | N6: Calculation | P6: Assumption
D7: Made by J.H | I7: Target Price : | K7: =+DCF!F43 -> 102000 | N7: Reference | P7: Notes
H10: Historical | K10: Forcast | P10: CAGR | R10: Notes
B11: (KRW B, unless stated otherwise) | H11: 44926 | I11: =+DATE(YEAR(H11)+1,MONTH(H11),DAY(H11)) -> 45291 | J11: =+DATE(YEAR(I11)+1,MONTH(I11),DAY(I11)) -> 45657 | K11: =+DATE(YEAR(J11)+1,MONTH(J11),DAY(J11)) -> 46022 | L11: =+DATE(YEAR(K11)+1,MONTH(K11),DAY(K11)) -> 46387 | M11: =+DATE(YEAR(L11)+1,MONTH(L11),DAY(L11)) -> 46752 | N11: =+DATE(YEAR(M11)+1,MONTH(M11),DAY(M11)) -> 47118 | O11: =+DATE(YEAR(N11)+1,MONTH(N11),DAY(N11)) -> 47483 | P11: 22A-24A | Q11: 24A-29F
A13: x | B13: [Income Statement]
B15: Revenue | H15: =+'3s'!C53/10^9 -> 18.635704 | I15: =+'3s'!D53/10^9 -> 70.196781 | J15: =+'3s'!E53/10^9 -> 108.66591 | K15: =+EBIT!K15 -> 157.85652 | L15: =+EBIT!L15 -> 197.47131 | M15: =+EBIT!M15 -> 243.07046 | N15: =+EBIT!N15 -> 295.88766 | O15: =+EBIT!O15 -> 354.90822
B16: growth(%) | I16: =+I15/H15-1 -> 2.7667898 | J16: =+J15/I15-1 -> 0.54801847 | K16: =+K15/J15-1 -> 0.45267743 | L16: =+L15/K15-1 -> 0.25095444 | M16: =+M15/L15-1 -> 0.23091528 | N16: =+N15/M15-1 -> 0.21729173 | O16: =+O15/N15-1 -> 0.1994695
B17: (-) COGS | H17: =+'3s'!C54/10^9 -> 10.96867 | I17: =+'3s'!D54/10^9 -> 60.966277 | J17: =+'3s'!E54/10^9 -> 75.461607 | K17: =+EBIT!K55 -> 93.560792 | L17: =+EBIT!L55 -> 117.52063 | M17: =+EBIT!M55 -> 147.76656 | N17: =+EBIT!N55 -> 175.15506 | O17: =+EBIT!O55 -> 205.6763
B18: Gross Profit | H18: =+'3s'!C55/10^9 -> 7.6670338 | I18: =+'3s'!D55/10^9 -> 9.2305039 | J18: =+'3s'!E55/10^9 -> 33.204306 | K18: =+K15-K17 -> 64.295727 | L18: =+L15-L17 -> 79.950682 | M18: =+M15-M17 -> 95.303895 | N18: =+N15-N17 -> 120.7326 | O18: =+O15-O17 -> 149.23192
B19: margin(%) | H19: =+H18/H15 -> 0.41141637 | I19: =+I18/I15 -> 0.13149469 | J19: =+J18/J15 -> 0.30556322 | K19: =+K18/K15 -> 0.40730486 | L19: =+L18/L15 -> 0.40487239 | M19: =+M18/M15 -> 0.39208341 | N19: =+N18/N15 -> 0.40803528 | O19: =+O18/O15 -> 0.42048031
B20: (-) SG&A | H20: =+'3s'!C56/10^9 -> 5.119061 | I20: =+'3s'!D56/10^9 -> 6.355443 | J20: =+'3s'!E56/10^9 -> 9.5652776 | K20: =+EBIT!K91 -> 11.950628 | L20: =+EBIT!L91 -> 14.242754 | M20: =+EBIT!M91 -> 17.064632 | N20: =+EBIT!N91 -> 19.865494 | O20: =+EBIT!O91 -> 22.813376
B21: Operating Profit (EBIT) | H21: =+'3s'!C57/10^9 -> 2.5479729 | I21: =+'3s'!D57/10^9 -> 2.8750609 | J21: =+'3s'!E57/10^9 -> 23.639029 | K21: =+K18-K20 -> 52.345099 | L21: =+L18-L20 -> 65.707929 | M21: =+M18-M20 -> 78.239263 | N21: =+N18-N20 -> 100.86711 | O21: =+O18-O20 -> 126.41855
B22: margin(%) | H22: =+H21/H15 -> 0.13672533 | I22: =+I21/I15 -> 0.040957162 | J22: =+J21/J15 -> 0.21753858 | K22: =+K21/K15 -> 0.33159922 | L22: =+L21/L15 -> 0.3327467 | M22: =+M21/M15 -> 0.32187895 | N22: =+N21/N15 -> 0.34089664 | O22: =+O21/O15 -> 0.35620066
B23: (+) Interest Income | H23: =+'3s'!C61/10^9 -> 0.14093906 | I23: =+'3s'!D61/10^9 -> 0.4186877 | J23: =+'3s'!E61/10^9 -> 0.054903554 | K23: =+J23 -> 0.054903554 | L23: =+K23 -> 0.054903554 | M23: =+L23 -> 0.054903554 | N23: =+M23 -> 0.054903554 | O23: =+N23 -> 0.054903554
B24: (-) Interest Expense | H24: =+'3s'!C64/10^9 -> 0.80462865 | I24: =+'3s'!D64/10^9 -> 2.9280821 | J24: =+'3s'!E64/10^9 -> 5.2504781 | K24: =+K162 -> 2.1772008 | L24: =+L162 -> 2.1165816 | M24: =+M162 -> 2.2687827 | N24: =+N162 -> 2.328827 | O24: =+O162 -> 2.4520466
B25: (+/-) Other Income / Expense | H25: =+('3s'!C58-'3s'!C59+'3s'!C62-'3s'!C65+'3s'!C66)/10^9 -> -1.7937927 | I25: =+('3s'!D58-'3s'!D59+'3s'!D62-'3s'!D65+'3s'!D66)/10^9 -> -50.463073 | J25: =+('3s'!E58-'3s'!E59+'3s'!E62-'3s'!E65+'3s'!E66)/10^9 -> -3.25771 | K25: =-('3s'!L244+'3s'!L248)/10^9 -> -70.767518 | L25: 0 | M25: 0 | N25: 0 | O25: 0
B26: Pretax Profit (EBT) | H26: =+'3s'!C67/10^9 -> 0.090490621 | I26: =+'3s'!D67/10^9 -> -50.097407 | J26: =+'3s'!E67/10^9 -> 15.185744 | K26: =+K21+K23-K24+K25 -> -20.544717 | L26: =+L21+L23-L24+L25 -> 63.646251 | M26: =+M21+M23-M24+M25 -> 76.025384 | N26: =+N21+N23-N24+N25 -> 98.593187 | O26: =+O21+O23-O24+O25 -> 124.0214
B27: (-) Corporate Tax | H27: =+'3s'!C68/10^9 -> 0.12309273 | I27: =+'3s'!D68/10^9 -> -2.7084131 | J27: =+'3s'!E68/10^9 -> 1.68208 | K27: =+K179 -> -5.649797 | L27: =+L179 -> 14.940393 | M27: =+M179 -> 17.936143 | N27: =+N179 -> 23.397551 | O27: =+O179 -> 29.551179
B28: Tax Rate (%) | H28: =+H27/H26 -> 1.3602816 | I28: =+I27/I26 -> 0.054062941 | J28: =+J27/J26 -> 0.11076704 | K28: =+K27/K26 -> 0.275 | L28: =+L27/L26 -> 0.23474113 | M28: =+M27/M26 -> 0.23592308 | N28: =+N27/N26 -> 0.23731408 | O28: =+O27/O26 -> 0.23827484
B29: Net Income | H29: =+'3s'!C69/10^9 -> -0.03260211 | I29: =+'3s'!D69/10^9 -> -47.388994 | J29: =+'3s'!E69/10^9 -> 13.503664 | K29: =+K26-K27 -> -14.894919 | L29: =+L26-L27 -> 48.705858 | M29: =+M26-M27 -> 58.089241 | N29: =+N26-N27 -> 75.195635 | O29: =+O26-O27 -> 94.470223
B30: margin(%) | H30: =+H29/H15 -> -0.0017494434 | I30: =+I29/I15 -> -0.67508785 | J30: =+J29/J15 -> 0.12426771 | K30: =+K29/K15 -> -0.094357329 | L30: =+L29/L15 -> 0.24664776 | M30: =+M29/M15 -> 0.23898108 | N30: =+N29/N15 -> 0.25413576 | O30: =+O29/O15 -> 0.26618212
A32: x | B32: [Balance Sheet]
B34: Total Assets | H34: =+'3s'!C22/10^9 -> 116.09099 | I34: =+'3s'!D22/10^9 -> 164.56716 | J34: =+'3s'!E22/10^9 -> 180.35687 | K34: =+K35+K40 -> 293.8591 | L34: =+L35+L40 -> 356.2356 | M34: =+M35+M40 -> 420.69398 | N34: =+N35+N40 -> 507.28363 | O34: =+O35+O40 -> 613.15034
B35: Current Assets | H35: =+'3s'!C5/10^9 -> 65.986781 | I35: =+'3s'!D5/10^9 -> 63.970787 | J35: =+'3s'!E5/10^9 -> 67.687584 | K35: =+SUM(K36:K39) -> 172.60601 | L35: =+SUM(L36:L39) -> 201.13229 | M35: =+SUM(M36:M39) -> 257.34914 | N35: =+SUM(N36:N39) -> 339.40442 | O35: =+SUM(O36:O39) -> 440.52654
B36: Cash & Equivalents | H36: =+'3s'!C6/10^9 -> 28.012486 | I36: =+'3s'!D6/10^9 -> 22.726383 | J36: =+'3s'!E6/10^9 -> 24.742642 | K36: =+J36+K88 -> 116.9311 | L36: =+K36+L88 -> 131.26674 | M36: =+L36+M88 -> 169.93477 | N36: =+M36+N88 -> 235.1453 | O36: =+N36+O88 -> 317.48252
B37: Accounts Receivables | H37: =+'3s'!C7/10^9 -> 3.4732903 | I37: =+'3s'!D7/10^9 -> 7.8674669 | J37: =+'3s'!E7/10^9 -> 9.3420341 | K37: =+K99 -> 12.625656 | L37: =+L99 -> 15.794121 | M37: =+M99 -> 19.441225 | N37: =+N99 -> 23.665642 | O37: =+O99 -> 28.386216
B38: Inventory | H38: =+'3s'!C12/10^9 -> 24.24869 | I38: =+'3s'!D12/10^9 -> 33.139258 | J38: =+'3s'!E12/10^9 -> 33.301516 | K38: =+K100 -> 42.61143 | L38: =+L100 -> 53.523726 | M38: =+M100 -> 67.298966 | N38: =+N100 -> 79.772811 | O38: =+O100 -> 93.673442
B39: Other Current Assets | H39: =+('3s'!C10+'3s'!C11+'3s'!C13)/10^9 -> 10.252314 | I39: =+('3s'!D10+'3s'!D11+'3s'!D13)/10^9 -> 0.23767863 | J39: =+('3s'!E10+'3s'!E11+'3s'!E13)/10^9 -> 0.3013928 | K39: =+K101 -> 0.43782652 | L39: =+L101 -> 0.54770102 | M39: =+M101 -> 0.67417356 | N39: =+N101 -> 0.8206659 | O39: =+O101 -> 0.98436372
B40: Non - Current Assets | H40: =+'3s'!C14/10^9 -> 50.104209 | I40: =+'3s'!D14/10^9 -> 100.59638 | J40: =+'3s'!E14/10^9 -> 112.66928 | K40: =+SUM(K41:K43) -> 121.25309 | L40: =+SUM(L41:L43) -> 155.10331 | M40: =+SUM(M41:M43) -> 163.34484 | N40: =+SUM(N41:N43) -> 167.87921 | O40: =+SUM(O41:O43) -> 172.62379
B41: PPE | H41: =+'3s'!C18/10^9 -> 45.72107 | I41: =+'3s'!D18/10^9 -> 91.539926 | J41: =+'3s'!E18/10^9 -> 100.151 | K41: =+K126 -> 108.06463 | L41: =+L126 -> 141.16898 | M41: =+M126 -> 148.57115 | N41: =+N126 -> 152.1517 | O41: =+O126 -> 155.81855
B42: I.A | H42: =+'3s'!C20/10^9 -> 0.20216783 | I42: =+'3s'!D20/10^9 -> 0.54383849 | J42: =+'3s'!E20/10^9 -> 1.1961402 | K42: =+K133 -> 1.8663192 | L42: =+L133 -> 2.6121819 | M42: =+M133 -> 3.4515505 | N42: =+N133 -> 4.4053662 | O42: =+O133 -> 5.4831049
B43: Other Non - Current Assets | H43: =+(SUM('3s'!C15:C17)+SUM('3s'!C19:C21))/10^9-H42 -> 4.1809708 | I43: =+(SUM('3s'!D15:D17)+SUM('3s'!D19:D21))/10^9-I42 -> 8.5126123 | J43: =+(SUM('3s'!E15:E17)+SUM('3s'!E19:E21))/10^9-J42 -> 11.322142 | K43: =+J43 -> 11.322142 | L43: =+K43 -> 11.322142 | M43: =+L43 -> 11.322142 | N43: =+M43 -> 11.322142 | O43: =+N43 -> 11.322142
B45: Total Liabilities | H45: =+'3s'!C38/10^9 -> 137.8424 | I45: =+'3s'!D38/10^9 -> 218.76899 | J45: =+'3s'!E38/10^9 -> 218.31254 | K45: =+K46+K53 -> 105.28015 | L45: =+L46+L53 -> 118.92187 | M45: =+M46+M53 -> 125.26036 | N45: =+N46+N53 -> 136.6219 | O45: =+O46+O53 -> 147.98394
B46: Current Liabilities | H46: =+'3s'!C24/10^9 -> 104.85671 | I46: =+'3s'!D24/10^9 -> 195.36515 | J46: =+'3s'!E24/10^9 -> 203.20902 | K46: =+SUM(K47:K52) -> 90.305628 | L46: =+SUM(L47:L52) -> 110.66935 | M46: =+SUM(M47:M52) -> 122.29584 | N46: =+SUM(N47:N52) -> 135.07935 | O46: =+SUM(O47:O52) -> 147.86337
B47: Account Payables | H47: =+'3s'!C25/10^9 -> 2.4248099 | I47: =+'3s'!D25/10^9 -> 16.338817 | J47: =+'3s'!E25/10^9 -> 13.928612 | K47: =+K104 -> 21.207225 | L47: =+L104 -> 26.529272 | M47: =+M104 -> 32.655286 | N47: =+N104 -> 39.75101 | O47: =+O104 -> 47.680124
B48: Short - Term Debt | H48: =+SUM('3s'!C26:C27)/10^9 -> 4.9686074 | I48: =+SUM('3s'!D26:D27)/10^9 -> 28.740074 | J48: =+SUM('3s'!E26:E27)/10^9 -> 30.281092 | K48: =+K145 -> 19.241092 | L48: =+L145 -> 32.941092 | M48: =+M145 -> 36.941092 | N48: =+N145 -> 40.941092 | O48: =+O145 -> 43.941092
B49: RCPS | H49: =+'3s'!C29/10^9 -> 17.855795 | I49: =+'3s'!D29/10^9 -> 21.127537 | J49: =+'3s'!E29/10^9 -> 25.084899 | K49: =+K158 -> 8.0311603 | L49: =+L158 -> 8.5130299 | M49: =+M158 -> 9.0238117 | N49: =+N158 -> 9.5652404 | O49: =+O158 -> 10.139155
B50: Derivatives | H50: =+'3s'!C30/10^9 -> 66.869214 | I50: =+'3s'!D30/10^9 -> 106.07166 | J50: =+'3s'!E30/10^9 -> 110.14033 | K50: 38.4 | L50: 38.4 | M50: 38.4 | N50: 38.4 | O50: 38.4 | R50: 자회사(셀릭) RCPS 분석 (26년도 상환 미가정)
...

Sheet EBIT
D3: CMTX(388210.KQ)
I5: Circuit Swith : | K5: N/A | N5: Hardcode | P5: Caution
D6: Three Statement Model | I6: Current Scenario : | K6: BASE CASE | N6: Calculation | P6: Assumption
D7: Made by J.H | I7: Target Price : | K7: =+DCF!F43 -> 102000 | N7: Reference | P7: Notes
H10: Historical | K10: Forcast | P10: CAGR | R10: Notes
H11: 44926 | I11: =+DATE(YEAR(H11)+1,MONTH(H11),DAY(H11)) -> 45291 | J11: =+DATE(YEAR(I11)+1,MONTH(I11),DAY(I11)) -> 45657 | K11: =+DATE(YEAR(J11)+1,MONTH(J11),DAY(J11)) -> 46022 | L11: =+DATE(YEAR(K11)+1,MONTH(K11),DAY(K11)) -> 46387 | M11: =+DATE(YEAR(L11)+1,MONTH(L11),DAY(L11)) -> 46752 | N11: =+DATE(YEAR(M11)+1,MONTH(M11),DAY(M11)) -> 47118 | O11: =+DATE(YEAR(N11)+1,MONTH(N11),DAY(N11)) -> 47483 | P11: 22A-24A | Q11: 24A-29F
A13: x | B13: [Revenue]
B15: Total Revenue | H15: =+'3s'!C53/10^9 -> 18.635704 | I15: =+'3s'!D53/10^9 -> 70.196781 | J15: =+'3s'!E53/10^9 -> 108.66591 | K15: =+K17+K19+K21 -> 157.85652 | L15: =+L17+L19+L21 -> 197.47131 | M15: =+M17+M19+M21 -> 243.07046 | N15: =+N17+N19+N21 -> 295.88766 | O15: =+O17+O19+O21 -> 354.90822
B16: yoy(%) | I16: =+I15/H15-1 -> 2.7667898 | J16: =+J15/I15-1 -> 0.54801847 | K16: =+K15/J15-1 -> 0.45267743 | L16: =+L15/K15-1 -> 0.25095444 | M16: =+M15/L15-1 -> 0.23091528 | N16: =+N15/M15-1 -> 0.21729173 | O16: =+O15/N15-1 -> 0.1994695
B17: 1. Samsung Electronics | I17: =+RAW!B17/10^3 -> 46.647 | J17: =+RAW!D17/10^3 -> 94.602 | K17: =+K29 -> 128.1019 | L17: =+L29 -> 159.91387 | M17: =+M29 -> 195.55182 | N17: =+N29 -> 235.3955 | O17: =+O29 -> 279.8591 | R17: <- Historical 하게 sec/(국내+중국) 비중 90% 이상 유지
B18: % of Sales | I18: =+I17/I15 -> 0.66451765 | J18: =+J17/J15 -> 0.87057659 | K18: =+K17/K15 -> 0.81150845 | L18: =+L17/L15 -> 0.8098081 | M18: =+M17/M15 -> 0.80450673 | N18: =+N17/N15 -> 0.79555701 | O18: =+O17/O15 -> 0.78853934
B19: 2. TSMC | H19: 0 | I19: 0 | J19: 0 | K19: =+K41 -> 4 | L19: =+L41 -> 10 | M19: =+M41 -> 18.032175 | N19: =+N41 -> 28.941641 | O19: =+O41 -> 41.290074
B20: % of Sales | I20: =+I19/I15 -> 0 | J20: =+J19/J15 -> 0 | K20: =+K19/K15 -> 0.025339467 | L20: =+L19/L15 -> 0.050640267 | M20: =+M19/M15 -> 0.074184971 | N20: =+N19/N15 -> 0.097812936 | O20: =+O19/O15 -> 0.11634015
B21: 3. Others | I21: =+I49 -> 23.55 | J21: =+J49 -> 14.064 | K21: =+K49 -> 25.75462 | L21: =+L49 -> 27.557444 | M21: =+M49 -> 29.486465 | N21: =+N49 -> 31.550517 | O21: =+O49 -> 33.759053
B22: % of Sales | I22: =+I21/I15 -> 0.33548547 | J22: =+J21/J15 -> 0.12942421 | K22: =+K21/K15 -> 0.16315208 | L22: =+L21/L15 -> 0.13955163 | M22: =+M21/M15 -> 0.1213083 | N22: =+N21/N15 -> 0.10663005 | O22: =+O21/O15 -> 0.095120516
A24: x | B24: [Revenue Driver]
B26: Si Parts Market Size | K26: 2500 | L26: =+K26*(1+L27) -> 2675 | M26: =+L26*(1+M27) -> 2862.25 | N26: =+M26*(1+N27) -> 3062.6075 | O26: =+N26*(1+O27) -> 3276.99
B27: yoy(%) | L27: 0.07 | M27: 0.07 | N27: 0.07 | O27: 0.07 | R27: cmtx 추정치 사용
B29: 1. For Samsung Electronics | I29: =+I17 -> 46.647 | J29: =+J17 -> 94.602 | K29: =+J37 -> 128.1019 | L29: =+L30*L33 -> 159.91387 | M29: =+M30*M33 -> 195.55182 | N29: =+N30*N33 -> 235.3955 | O29: =+O30*O33 -> 279.8591
B30: Si Parts Market Size to SEC | K30: =+K29/K33 -> 854.01266 | L30: =+K30*(1+L27) -> 913.79355 | M30: =+L30*(1+M27) -> 977.75909 | N30: =+M30*(1+N27) -> 1046.2022 | O30: =+N30*(1+O27) -> 1119.4364 | R30: Si 파츠 시장 내 SEC 포지션은 동일함 가정
B32: After Market Ratio | J32: 0.25 | K32: 0.3 | L32: 0.35 | M32: 0.4 | N32: 0.45 | O32: 0.5 | R32: 업계 추정치 및 컨콜 참고한 가정
B33: M/S In SEC (Si) | J33: =+J32*0.5 -> 0.125 | K33: 0.15 | L33: =+L32*0.5 -> 0.175 | M33: =+M32*0.5 -> 0.2 | N33: =+N32*0.5 -> 0.225 | O33: 0.25 | R33: HALF of A/M 가정
D35: 2025 SEC향 실적 추정
D36: 2Q 24 | E36: 3Q 24 | F36: 4Q 24 | G36: 1Q 25 | H36: 2Q 25 | I36: 3Q 25 | J36: 4Q 25
C37: Sales | D37: =+RAW!T17/10^9 -> 33.783863 | E37: =+RAW!K16/10^9 -> 63.189977 | F37: =+RAW!S22/10^9 -> 94.601716 | H37: =+RAW!F17/10^3 -> 65.418 | I37: =+RAW!J16/10^9 -> 98.101899 | J37: =+I37+J39 -> 128.1019 | R37: 25년 1분기 데이터 공백(비상장)
C38: YOY | H38: =+H37/D37-1 -> 0.93636828 | I38: =+I37/E37-1 -> 0.55249146
C39: incremental | H39: =+H37-D37 -> 31.634137 | I39: =+I37-E37 -> 34.911922 | J39: 30
B41: 2. For TSMC | K41: =+K46 -> 4 | L41: =+L46 -> 10 | M41: =+M42*M47 -> 18.032175 | N41: =+N42*N47 -> 28.941641 | O41: =+O42*O47 -> 41.290074
B42: Si Parts Market Size to TSMC | K42: =+K26*K43*K44 -> 787.5 | L42: =+L26*L43*L44 -> 842.625 | M42: =+M26*M43*M44 -> 901.60875 | N42: =+N26*N43*N44 -> 964.72136 | O42: =+O26*O43*O44 -> 1032.2519
B43: Non - Memory Ratio in Si parts Market(%) | K43: 0.45 | L43: 0.45 | M43: 0.45 | N43: 0.45 | O43: 0.45
B44: TSMC M/S(%) | K44: 0.7 | L44: 0.7 | M44: 0.7 | N44: 0.7 | O44: 0.7
B46: Guidance | K46: 4 | L46: 10
B47: M/S in TSMC | K47: =+K46/K42 -> 0.0050793651 | L47: =+L46/L42 -> 0.011867675 | M47: 0.02 | N47: 0.03 | O47: 0.04
B49: 3. For Others | I49: =+RAW!B18/10^3 -> 23.55 | J49: =+RAW!D18/10^3 -> 14.064 | K49: =+K50*K51 -> 25.75462 | L49: =+L50*L51 -> 27.557444 | M49: =+M50*M51 -> 29.486465 | N49: =+N50*N51 -> 31.550517 | O49: =+O50*O51 -> 33.759053
B50: Si Parts Market Size to Others | K50: =+K26-K30-K42 -> 858.48734 | L50: =+L26-L30-L42 -> 918.58145 | M50: =+M26-M30-M42 -> 982.88216 | N50: =+N26-N30-N42 -> 1051.6839 | O50: =+O26-O30-O42 -> 1125.3018
B51: M/S in Others(%) | K51: 0.03 | L51: 0.03 | M51: 0.03 | N51: 0.03 | O51: 0.03 | R51: 주관이 개입될 여지가 높은 추정
A53: x | B53: [COGS]
B55: COGS | H55: =+Model!H17 -> 10.96867 | I55: =+Model!I17 -> 60.966277 | J55: =+Model!J17 -> 75.461607 | K55: =+K62+K70+K72+K75+K76+K78+K80+K82+K84+K86 -> 93.560792 | L55: =+L62+L70+L72+L75+L76+L78+L80+L82+L84+L86 -> 117.52063 | M55: =+M62+M70+M72+M75+M76+M78+M80+M82+M84+M86 -> 147.76656 | N55: =+N62+N70+N72+N75+N76+N78+N80+N82+N84+N86 -> 175.15506 | O55: =+O62+O70+O72+O75+O76+O78+O80+O82+O84+O86 -> 205.6763
B57: Gross Profit | H57: =+H15-H55 -> 7.6670338 | I57: =+I15-I55 -> 9.2305039 | J57: =+J15-J55 -> 33.204306 | K57: =+K15-K55 -> 64.295727 | L57: =+L15-L55 -> 79.950682 | M57: =+M15-M55 -> 95.303895 | N57: =+N15-N55 -> 120.7326 | O57: =+O15-O55 -> 149.23192
B58: GPM(%) | H58: =+H57/H15 -> 0.41141637 | I58: =+I57/I15 -> 0.13149469 | J58: =+J57/J15 -> 0.30556322 | K58: =+K57/K15 -> 0.40730486 | L58: =+L57/L15 -> 0.40487239 | M58: =+M57/M15 -> 0.39208341 | N58: =+N57/N15 -> 0.40803528 | O58: =+O57/O15 -> 0.42048031
...

Sheet -> Back Data
E14: Blank Page

Sheet Chart pack
B2: 경쟁사 분석 페이지에 들어갈 테이블
B4: (단위 : 억 원) | F4: FY2023 | I4: FY2024 | L4: FY2025(E) | O4: FY2026(E)
C5: Market | D5: Segment | E5: Customer | F5: Sales | G5: YoY | H5: OPM | I5: Sales | J5: YoY | K5: OPM | L5: Sales | M5: YoY | N5: OPM | O5: Sales | P5: YoY | Q5: OPM
B6: 씨엠티엑스 | C6: A/M | D6: Si / Sapphire | E6: 삼성전자, TSMC | F6: 702 | G6: =3.7741935483871-1 -> 2.7741935 | H6: 0.041 | I6: 1087 | J6: =+I6/F6-1 -> 0.54843305 | K6: 0.2175 | L6: =+EBIT!K15*10 -> 1578.5652 | M6: =+L6/I6-1 -> 0.45222189 | N6: =+Model!K22 -> 0.33159922 | O6: =+EBIT!L15*10 -> 1974.7131 | P6: =+O6/L6-1 -> 0.25095444 | Q6: =+Model!L22 -> 0.3327467
B7: 월덱스 | C7: A/M | D7: Si / Quartz | E7: 삼성전자, SK하이닉스 | F7: 2881 | G7: =1.12583040250098-1 -> 0.1258304 | H7: 0.225 | I7: 3068 | J7: =+I7/F7-1 -> 0.064908018 | K7: 0.229 | L7: 2991 | M7: =+L7/I7-1 -> -0.025097784 | N7: 0.199 | O7: 3338 | P7: =+O7/L7-1 -> 0.11601471 | Q7: 0.225
B8: 케이엔제이 | C8: A/M | D8: SiC | E8: 삼성전자, SK하이닉스 | F8: 474 | G8: =0.760834670947031-1 -> -0.23916533 | H8: 0.2212 | I8: 622 | J8: =+I8/F8-1 -> 0.31223629 | K8: 0.227 | L8: 839 | M8: =+L8/I8-1 -> 0.3488746 | N8: 0.265 | O8: 1060 | P8: =+O8/L8-1 -> 0.26340882 | Q8: 0.281
B9: 하나머티리얼즈 | C9: B/M | D9: Si / SiC | E9: TEL, 삼성전자 | F9: 2336 | G9: =+F9/3073-1 -> -0.23983078 | H9: 0.176 | I9: 2516 | J9: =+I9/F9-1 -> 0.077054795 | K9: 0.172 | L9: 2643 | M9: =+L9/I9-1 -> 0.050476948 | N9: 0.174 | O9: 2978 | P9: =+O9/L9-1 -> 0.12674991 | Q9: 0.234
B10: 티씨케이 | C10: B/M | D10: SiC | E10: TEL, 삼성전자 | F10: 2267 | G10: =+F10/3196-1 -> -0.29067584 | H10: 0.294 | I10: 2757 | J10: =+I10/F10-1 -> 0.21614468 | K10: 0.292 | L10: 3143 | M10: =+L10/I10-1 -> 0.14000725 | N10: 0.285 | O10: 3718 | P10: =+O10/L10-1 -> 0.18294623 | Q10: 0.305
B11: 비씨엔씨 | C11: A/M + B/M | D11: Si / Ceramic | E11: 삼성전자, SK하이닉스 | F11: 653 | G11: =+F11/821-1 -> -0.2046285 | H11: -0.0006 | I11: 774 | J11: =+I11/F11-1 -> 0.18529862 | K11: -0.0267 | L11: 914 | M11: =+L11/I11-1 -> 0.18087855 | N11: 0.0619 | O11: 1165 | P11: =+O11/L11-1 -> 0.27461707 | Q11: 0.1048
B13: 출처 : 각 사, Dart , Fn가이드
B15: 도표 1-1. 디램 재고 수준
C17: 4Q 24 | D17: 2Q 25 | E17: 3Q 25 | F17: 4Q 25
B18: Dram Suppliers | C18: 13~17주 | D18: 6~13주 | E18: 3~8주 | F18: 2~4주
B19: Smartphones | C19: 6~8주 | D19: 4~6주 | E19: 4~6주 | F19: 2~4주
B20: Enterprise | C20: 13~14주 | D20: 9~10주 | E20: 8~9주 | F20: 7~8주
B21: Major Modules Houses | C21: 11~16주 | D21: 9~14주 | E21: 8~12주 | F21: 7~10주
B22: Hyperscalers | C22: 12~15주 | D22: 11~15주 | E22: 12~15주 | F22: 10~13주
B23: PC OEMs | C23: 10~16주 | D23: 12~15주 | E23: 12~15주 | F23: 10~13주
B25: 도표 1-2. 삼성전자, SK하이닉스 분기별 OPM
C27: 1Q 24 | D27: 2Q 24 | E27: 3Q 24 | F27: 4Q 24 | G27: 1Q 25 | H27: 2Q 25 | I27: 3Q 25
B28: 삼성전자(DS부문) | C28: =1912015/23137290 -> 0.082637811 | D28: =5554284/28093113 -> 0.19770981 | E28: =3684208/29271373 -> 0.12586386 | F28: =15094486/111065950 -> 0.13590561 | G28: =1105503/25131006 -> 0.043989604 | H28: =350173/27875087 -> 0.012562221 | I28: =6991305/33116787 -> 0.21111061
B29: SK하이닉스 | C29: =2886029/12429598 -> 0.23219005 | D29: =5468536/16423258 -> 0.3329751 | E29: 0.4 | F29: 0.41 | G29: 0.42 | H29: 0.41 | I29: 0.47
B40: 도표 1-3. 삼성전자, SK하이닉스 최근 1년 주가
B56: 도표 1-4. 전공정 부품 기업 최근 1년 주가
B72: 도표 1-5. 삼성전자/SK하이닉스 CAPEX
C73: 2025 | D73: 2026 | E73: 2027 | F73: 2028
B74: 삼성전자
B75: P4 | C75: Ph1. 하이브리드 라인
C76: Ph3. D램 전용
D77: Ph4. D램 전용
E78: Ph2. 파운드리 or D램 예상
B79: P5 | F79: Fab 준공
B80: SK하이닉스
B81: M15X | D81: D램 전용 가동
B82: Y1 | E82: Fab 준공
B84: 도표 1-8. 건식식각 vs 습식식각
C86: 건식 식각 | D86: 습식 식각
B87: 방법 | C87: 물리적, 화학적 반응 | D87: 화학적 반응
B88: 장점 | C88: 높은 정확도 | D88: 저비용 및 쉬운 과정
C89: 미세 패터닝 가능 | D89: 식각 속도가 빠름
...

Sheet 3s
B1: 단위(원)
B2: 과목 | C2: 2022년 | D2: 2023년 | E2: 2024년 | F2: 2025년 반기
C3: (제 10 기말) | D3: (제 11 기말) | E3: (제 12 기말) | F3: (제 13 기 반기말)
B4: 자산
B5: 유동자산 | C5: 65986780946 | D5: 63970786965 | E5: 67687584185 | F5: 83269124410
B6: 현금및현금성자산 | C6: 28012486271 | D6: 22726383499 | E6: 24742641689 | F6: 27251464400
B7: 매출채권 및 기타유동채권 | C7: 3473290340 | D7: 7867466865 | E7: 9342034134 | F7: 14423534762
B8: 매출채권 | C8: 3081758049 | D8: 3463709575 | E8: 6951444141
B9: 기타유동채권 | C9: =+C7-C8 -> 391532291 | D9: =+D7-D8 -> 4403757290 | E9: =+E7-E8 -> 2390589993
B10: 기타유동자산 | C10: 251664501 | D10: 155541213 | E10: 281392799 | F10: 1127273601
B11: 기타금융자산 | C11: 10000000000 | D11: 43229631 | E11: 20000000 | F11: 49173724
B12: 재고자산 | C12: 24248690094 | D12: 33139257967 | E12: 33301515563 | F12: 40416654763
B13: 당기법인세자산 | C13: 649740 | D13: 38907790 | E13: 0 | F13: 1023160
B14: 비유동자산 | C14: 50104208950 | D14: 100596376971 | E14: 112669283405 | F14: 114014465059
B15: 종속기업 및 공동기업투자 | C15: 0 | D15: 0 | E15: 1968504053 | F15: 1561989649
B16: 기타비유동금융자산 | C16: 285672975 | D16: 365045929 | E16: 462190398 | F16: 420394623
B17: 기타비유동자산 | C17: 0 | D17: 131365192 | E17: 106339984 | F17: 93930226
B18: 유형자산 | C18: 45721070283 | D18: 91539926204 | E18: 100151000731 | F18: 101691321233
B19: 사용권자산 | C19: 184088435 | D19: 252162975 | E19: 282890571 | F19: 498239894
B20: 무형자산 | C20: 202167830 | D20: 543838489 | E20: 1196140238 | F20: 1168499744
B21: 이연법인세자산 | C21: 3711209427 | D21: 7764038182 | E21: 8502217430 | F21: 8580089690
B22: 자산총계 | C22: 116090989896 | D22: 164567163936 | E22: 180356867590 | F22: 197283589469
B23: 부채
B24: 유동부채 | C24: 104856707913 | D24: 195365147611 | E24: 203209023076 | F24: 85400497165
B25: 매입채무 및 기타부채 | C25: 2424809888 | D25: 16338816644 | E25: 13928611789 | F25: 12531168353
B26: 단기차입금 | C26: 2950000000 | D26: 20278800000 | E26: 28340000000 | F26: 23540000000
B27: 유동성장기차입금 | C27: 2018607374 | D27: 8461273992 | E27: 1941091992 | F27: 2761371992
B28: 유동성당기손익-공정가치측정금융부채 | C28: 12443822696 | D28: 21265442449 | E28: 21235486019 | F28: -
B29: 유동성전환상환우선주부채 | C29: 17855794552 | D29: 21127537259 | E29: 25084898741 | F29: 7510899957
B30: 유동성파생상품부채 | C30: 66869213520 | D30: 106071656198 | E30: 110140327181 | F30: 38457335662
B31: 유동 리스부채 | C31: 61017265 | D31: 98103639 | E31: 124798999 | F31: 137687459
B32: 당기법인세부채 | C32: 28610807 | D32: 481859115 | E32: 2051537780 | F32: -
B33: 기타 유동부채 | C33: 204831811 | D33: 1241658315 | E33: 362270575 | F33: 462033742
B34: 비유동부채 | C34: 32985695361 | D34: 23403844417 | E34: 15103520782 | F34: 13740842143
B35: 장기차입금 | C35: 31878648626 | D35: 23279042634 | E35: 14982950642 | F35: 13552384646
B36: 비유동 리스부채 | C36: 107046735 | D36: 124801783 | E36: 120570140 | F36: 188457497
B37: 사채 | C37: 1000000000 | D37: - | E37: - | F37: -
B38: 부채총계 | C38: 137842403274 | D38: 218768992028 | E38: 218312543858 | F38: 99141339308
B39: 자본
B40: 지배기업의 소유주에게 귀속되는 자본 | C40: -21767188116 | D40: -54359465973 | E40: -38475338487 | F40: 97545269707
...

Sheet RAW
A1: [씨엠티엑스 지역별 매출액 및 매출비중]
A2: (단위: 백만원)
A3: 구 분 | B3: 2023년 | D3: 2024년 | F3: 2025년 반기 | I3: 원 | J3: 25 3Q | K3: 24 3Q | M3: - 당분기 | N3: 25 3Q | S3: TSMC | T3: 대만
B4: 매출액 | C4: 매출비중 | D4: 매출액 | E4: 매출비중 | F4: 매출액 | G4: 매출비중 | I4: 구 분 | J4: 당분기 | K4: 전분기 | M4: (단위: 원) | S4: 마이크론 | T4: 대만 / 싱가폴
A5: 국내 | B5: 38533 | C5: 0.549 | D5: 43404 | E5: 0.399 | F5: 29723 | G5: 0.384 | I5: 국내 | J5: 45928286674 | K5: 26438724223 | M5: 구 분 | N5: 국내 | O5: 대만 | P5: 합 계 | S5: 키옥시아 | T5: 일본
A6: 중국 | B6: 24751 | C6: 0.353 | D6: 54715 | E6: 0.504 | F6: 40017 | G6: 0.517 | I6: 중국 | J6: 59887565685 | K6: 38714507422 | M6: 외부매출액 | N6: 116164825307 | O6: 2212096339 | P6: 118376921646 | S6: UMC | T6: 대만 / 싱가폴
A7: 대만 | B7: 1959 | C7: 0.028 | D7: 5086 | E7: 0.047 | F7: 3156 | G7: 0.041 | I7: 대만 | J7: 5382459389 | K7: 4208156318 | M7: 영업이익 | N7: 41956250674 | O7: -178383117 | P7: 41777867557 | S7: SMIC | T7: 중국
A8: 싱가포르 | B8: 3966 | C8: 0.057 | D8: 4396 | E8: 0.04 | F8: 3619 | G8: 0.047 | I8: 싱가포르 | J8: 5848772560 | K8: 2896981566 | M8: 유형자산 | N8: 102731538233 | O8: - | P8: 102731538233 | S8: PSMC | T8: 대만
A9: 기타 | B9: 988 | C9: 0.014 | D9: 1065 | E9: 0.01 | F9: 835 | G9: 0.011 | I9: 기타 | J9: 1329837338 | K9: 786423321 | M9: 무형자산 | N9: 1142281594 | O9: 5145114 | P9: 1147426708 | S9: 삼성전자 | T9: 한국 / 중국
A10: 합 계 | B10: 70197 | C10: 1 | D10: 108666 | E10: 1 | F10: 77350 | G10: 1 | I10: 합 계 | J10: 118376921646 | K10: 73044792850 | M10: 사용권자산 | N10: 482148370 | O10: - | P10: 482148370
A11: 국내 + 중국 | B11: =+B5+B6 -> 63284 | D11: =+D5+D6 -> 98119 | F11: =+F5+F6 -> 69740 | J11: =+J5+J6 -> 105815852359 | M11: 감가상각비 | N11: 7712571619 | O11: - | P11: 7712571619
M12: 무형자산상각비 | N12: 248858644 | O12: 1013669 | P12: 249872313
A13: [2023-2025년 반기 매출처별 매출액] | J13: =+J10-J16 -> 20275022646
A14: (단위: 백만원) | J14: 25 3Q | K14: 24 3Q | M14: - 당반기 | N14: 25 2Q
A15: 매출처 | B15: 2023년 | D15: 2024년 | F15: 2025년 반기 | I15: 구 분 | J15: 당분기 | K15: 전분기 | M15: (단위: 원) | R15: (단위: 원) | S15: 25 2Q | T15: 24 2Q
B16: 매출액 | C16: 비중 | D16: 매출액 | E16: 비중 | F16: 매출액 | G16: 비중 | I16: 삼성전자 | J16: 98101899000 | K16: 63189976600 | M16: 구 분 | N16: 국내 | O16: 대만 | P16: 합 계 | R16: 구 분 | S16: 당반기 | T16: 전반기
A17: 삼성전자 | B17: 46647 | C17: 0.6645 | D17: 94602 | E17: 0.8706 | F17: 65418 | G17: 0.8457 | M17: 외부매출액 | N17: 76341755346 | O17: 1008180320 | P17: 77349935666 | R17: 삼성전자 | S17: 65417641000 | T17: 33783862600
A18: 기타 | B18: 23550 | C18: 0.3355 | D18: 14064 | E18: 0.1294 | F18: 11932 | G18: 0.1543 | M18: 영업이익 | N18: 26443020320 | O18: -129952346 | P18: 26313067974
A19: 합계 | B19: 70197 | C19: 1 | D19: 108666 | E19: 1 | F19: 77350 | G19: 1 | M19: 유형자산 | N19: 101691321233 | O19: - | P19: 101691321233
A20: 삼성전자/(국내+중국) | B20: =+B17/B11 -> 0.73710575 | D20: =+D17/D11 -> 0.96415577 | F20: =+F17/F11 -> 0.93802696 | J20: =+J16/J11 -> 0.92710021 | M20: 무형자산 | N20: 1162767618 | O20: 5732126 | P20: 1168499744 | R20: (단위: 원) | S20: 24 4Q | T20: 23 4Q
M21: 사용권자산 | N21: 498239894 | O21: - | P21: 498239894 | R21: 구 분 | S21: 당 기 | T21: 전 기
A22: [연도별 시설자금 투자계획] | M22: 감가상각비 | N22: 4982938848 | O22: - | P22: 4982938848 | R22: 고객 A | S22: 94601715600 | T22: 46646516090
A23: (단위: 백만원) | M23: 무형자산상각비 | N23: 163172620 | O23: 500909 | P23: 163673529 | R23: 고객 B | S23: 2400000 | T23: 11956834000
A24: 구분 | B24: 내역 | C24: 2025년 | D24: 2026년 | E24: 2027년 | F24: 합계
A25: 설비증설 | B25: M Campus 공정 설비 증설 | C25: 1000 | D25: 7000 | E25: 3000 | F25: 11000
B26: C Campus 공정 설비 추가 | C26: 1000 | D26: 1000 | E26: 1000 | F26: 3000
B27: 공정 유틸리티 | C27: 500 | D27: 4500 | E27: - | F27: 5000
A28: 건물 신축 등 | B28: M Campus B동 건설 | C28: 2000 | D28: 13000 | E28: - | F28: 15000
B29: M Campus 주차타워 건설 | C29: 1000 | D29: 4000 | E29: - | F29: 5000
B30: C Campus 환경개선 | C30: - | D30: 1000 | E30: - | F30: 1000
A31: 시설자금 계 | C31: 5500 | D31: 30500 | E31: 4000 | F31: 40000
A34: [기간별 유통가능 주식수]
A35: (단위: 주)
A36: 구분 | B36: 주식수 | C36: 유통가능 주식수 비율
A37: 상장일 유통가능 | B37: 2965913 | C37: 0.3199
A38: 상장후 1개월 뒤 유통가능 | B38: 2002343 | C38: 0.5358
A39: 상장후 2개월 뒤 유통가능 | B39: 726631 | C39: 0.6142
A40: 상장후 3개월 뒤 유통가능 | B40: 743161 | C40: 0.6943
A41: 상장후 2년 6개월 뒤 유통가능 | B41: 2834640 | C41: 1
A44: - 당분기 | B44: 25/3Q
...

Sheet 자료 스크랩
B2: https://news.nate.com/view/20251120n23569
B3: - 상반기 기준 전자 점유율 15%
B4: - 생산능력은 5배 확대 / 2028년 해외매출 1,500억 목표
B5: - 실리콘이 세라믹보다 2배 저렴함
B7: chrome-extension://efaidnbmnnnibpcajpcglclefindmkaj/https://w4.kirs.or.kr/download/research/250818_%EC%BC%80%EC%9D%B4%EC%97%94%EC%A0%9C%EC%9D%B4.pdf
B8: - 케이엔제이 리포트
B10: chrome-extension://efaidnbmnnnibpcajpcglclefindmkaj/https://w4.kirs.or.kr/download/research/250703_%ED%95%98%EB%82%98%EB%A8%B8%ED%8B%B0%EB%A6%AC%EC%96%BC%EC%A6%88(%EA%B8%80%EC%84%B8).pdf
B11: - 하나머티리얼즈 리포트
B13: chrome-extension://efaidnbmnnnibpcajpcglclefindmkaj/https://w4.kirs.or.kr/download/research/250123_%ED%8B%B0%EC%94%A8%EC%BC%80%EC%9D%B4-%EA%B8%80%EB%A1%9C%EB%B2%8C%EC%84%B8%EA%B7%B8.pdf
B14: - 티씨케이 리포트
B16: https://n.news.naver.com/mnews/article/030/0003368294
B17: - CMTX CEO 인터뷰
... B59: 23년도 기준

Sheet 주담 문의
B2: 씨엠티엑스 주담(251210)
B3: Q1. 실리콘파츠 관련 점유율 확대에 대한 구체적 근거 있는지? 삼전 15% 상반기 점유율에서 확대 있었는지?
B4: A1. 구체적으로 말은 못하는데 수주 증가하는 추세 맞고 삼성전자외에도 TSMC, 키옥시아도 증가 추세다
B6: Q2. 대만쪽 JV가 TSMC 대응 목적인데 TSMC 매출이 JV에서 나오는 것인지?
B7: A2. JV에서 나가는 것도 있고 매출은 본사랑 JV랑 섞여있다.
B9: Q3. TSMC 올해 40~50억 내년 100~110억 가이던스 변화 없는지?
B10: A3. 특별한 변화는 없고 점차적으로 증가할 예정
B12: Q4. 공장 가동률이 70% 수준인데 지금 막 증설해야될 만큼 풀캐파는 아닌거 같다. 공모자금으로 캐파 증설하려는 목적이 애프터 마켓으로 확대되는 시점에서 가동률을 같이 올려줄려고 시기를 맞춘건지 아니면 다른 이유가 있는지?
B13: A4. 매출 증가를 준비하기 위해서 미리 생산 능력을 갖추려고 작업하고 있다.
B15: Q5. 디램이랑 낸드 비중은?
B16: A5. 낸드가 조금 더 크고 그 다음 디램이다
B18: Q6. 셀릭 RCPS 관련 외부투자자 상환권 요구시 셀릭 현금 유출 예상되는데 준비하는 거 있는지?
... B25: A8. 최초 법인 설립시 세라믹, 사파이어 위주로 진행했고 실리콘으로 넘어오면서 극대화된 것이다. 기존에 하는 제품들의 경우 고객사 요구가 있어서 주에서 부로 빠진 것이고 적자 상황 아니다.

Sheet peer
B1: Ticker | C1: Name | D1: Exchange | E1: price | F1: # of shares | G1: mk cap | H1: 23 | I1: 24 | J1: 25 | K1: 26
A2: #VALUE! | B2: 388210 | C2: {=+_FV(A2,"Name")} -> CMTX Co.,Ltd. | D2: {=+_FV(A2,"Exchange")} -> Korea Stock Exchange | E2: {=+_FV(A2,"Price")} -> 114900 | F2: {=+_FV(A2,"Shares outstanding",TRUE)} -> 9634440 | G2: {=+_FV(A2,"Market cap",TRUE)} -> 930977900000 | H2: 702 | I2: 1087 | J2: 1659 | K2: 2078
H3: 29 | I3: 236 | J3: 448 | K3: 512
A4: #VALUE! | B4: 101160 | C4: {=+_FV(A4,"Name")} -> WORLDEXINDUSTRY&TRADINGCO.,LTD | D4: {=+_FV(A4,"Exchange")} -> Korea Stock Exchange | E4: {=+_FV(A4,"Price")} -> 25900 | F4: {=+_FV(A4,"Shares outstanding",TRUE)} -> 16510990 | G4: {=+_FV(A4,"Market cap",TRUE)} -> 362416300000
A6: #VALUE! | B6: 272110 | C6: {=+_FV(A6,"Name")} -> KnJ Co.,Ltd. | D6: {=+_FV(A6,"Exchange")} -> Korea Stock Exchange | E6: {=+_FV(A6,"Price")} -> 32300 | F6: {=+_FV(A6,"Shares outstanding",TRUE)} -> 8025390 | G6: {=+_FV(A6,"Market cap",TRUE)} -> 164520600000
A8: #VALUE! | B8: 166090 | C8: {=+_FV(A8,"Name")} -> Hana Materials Inc. | D8: {=+_FV(A8,"Exchange")} -> Korea Stock Exchange | E8: {=+_FV(A8,"Price")} -> 69100 | F8: {=+_FV(A8,"Shares outstanding",TRUE)} -> 19777670 | G8: {=+_FV(A8,"Market cap",TRUE)} -> 915706300000
A10: #VALUE! | B10: 064760 | C10: {=+_FV(A10,"Name")} -> TOKAI CARBON KOREA Co., Ltd. | D10: {=+_FV(A10,"Exchange")} -> Korea Stock Exchange | E10: {=+_FV(A10,"Price")} -> 282000 | F10: {=+_FV(A10,"Shares outstanding",TRUE)} -> 11179420 | G10: {=+_FV(A10,"Market cap",TRUE)} -> 1755168000000
A12: #VALUE! | B12: 146320 | C12: {=+_FV(A12,"Name")} -> BCnC Co., Ltd. | D12: {=+_FV(A12,"Exchange")} -> Korea Stock Exchange | E12: {=+_FV(A12,"Price")} -> 15140 | F12: {=+_FV(A12,"Shares outstanding",TRUE)} -> 12797920 | G12: {=+_FV(A12,"Market cap",TRUE)} -> 176995300000

Sheet PRICE
A1: 일자 | B1: 삼성전자 | D1: SK하이닉스 | F1: 월덱스 | H1: 케이엔제이 | J1: 하나머티리얼즈 | L1: 티씨케이 | N1: 비씨엔씨
A2: 2024/12/10 | B2: 54000 | C2: 100 | D2: 170400 | E2: 100 | F2: 15720 | G2: 100 | H2: 12830 | I2: 100 | J2: 22700 | K2: 100 | L2: 67600 | M2: 100 | N2: 7810 | O2: 100
A3: 2024/12/11 | B3: 54000 | C3: =+C2*(1+(B3/B2-1)) -> 100 | D3: 171800 | E3: =+E2*(1+(D3/D2-1)) -> 100.8216 | F3: 15890 | G3: =+G2*(1+(F3/F2-1)) -> 101.08142 | H3: 13250 | I3: =+I2*(1+(H3/H2-1)) -> 103.27358 | J3: 23400 | K3: =+K2*(1+(J3/J2-1)) -> 103.0837 | L3: 71100 | M3: =+M2*(1+(L3/L2-1)) -> 105.17751 | N3: 8260 | O3: =+O2*(1+(N3/N2-1)) -> 105.76184
A4: 2024/12/12 | B4: 55900 | C4: =+C3*(1+(B4/B3-1)) -> 103.51852 | D4: 176100 | E4: =+E3*(1+(D4/D3-1)) -> 103.34507 | F4: 16380 | G4: =+G3*(1+(F4/F3-1)) -> 104.19847 | H4: 13130 | I4: =+I3*(1+(H4/H3-1)) -> 102.33827 | J4: 24000 | K4: =+K3*(1+(J4/J3-1)) -> 105.72687 | L4: 70600 | M4: =+M3*(1+(L4/L3-1)) -> 104.43787 | N4: 8350 | O4: =+O3*(1+(N4/N3-1)) -> 106.91421
A5: 2024/12/13 | B5: 56100 | C5: =+C4*(1+(B5/B4-1)) -> 103.88889 | D5: 175500 | E5: =+E4*(1+(D5/D4-1)) -> 102.99296 | F5: 16480 | G5: =+G4*(1+(F5/F4-1)) -> 104.83461 | H5: 13580 | I5: =+I4*(1+(H5/H4-1)) -> 105.84567 | J5: 23750 | K5: =+K4*(1+(J5/J4-1)) -> 104.62555 | L5: 70600 | M5: =+M4*(1+(L5/L4-1)) -> 104.43787 | N5: 8540 | O5: =+O4*(1+(N5/N4-1)) -> 109.34699
A6: 2024/12/16 | B6: 55600 | C6: =+C5*(1+(B6/B5-1)) -> 102.96296 | D6: 179300 | E6: =+E5*(1+(D6/D5-1)) -> 105.223 | F6: 16650 | G6: =+G5*(1+(F6/F5-1)) -> 105.91603 | H6: 13670 | I6: =+I5*(1+(H6/H5-1)) -> 106.54716 | J6: 23850 | K6: =+K5*(1+(J6/J5-1)) -> 105.06608 | L6: 71700 | M6: =+M5*(1+(L6/L5-1)) -> 106.06509 | N6: 8790 | O6: =+O5*(1+(N6/N5-1)) -> 112.54802
A7: 2024/12/17 | B7: 54200 | C7: =+C6*(1+(B7/B6-1)) -> 100.37037 | D7: 184000 | E7: =+E6*(1+(D7/D6-1)) -> 107.98122 | F7: 16850 | G7: =+G6*(1+(F7/F6-1)) -> 107.1883 | H7: 14060 | I7: =+I6*(1+(H7/H6-1)) -> 109.58691 | J7: 24150 | K7: =+K6*(1+(J7/J6-1)) -> 106.38767 | L7: 72000 | M7: =+M6*(1+(L7/L6-1)) -> 106.50888 | N7: 8850 | O7: =+O6*(1+(N7/N6-1)) -> 113.31626
A8: 2024/12/18 | B8: 54900 | C8: =+C7*(1+(B8/B7-1)) -> 101.66667 | D8: 183500 | E8: =+E7*(1+(D8/D7-1)) -> 107.68779 | F8: 16790 | G8: =+G7*(1+(F8/F7-1)) -> 106.80662 | H8: 13850 | I8: =+I7*(1+(H8/H7-1)) -> 107.95012 | J8: 24450 | K8: =+K7*(1+(J8/J7-1)) -> 107.70925 | L8: 72100 | M8: =+M7*(1+(L8/L7-1)) -> 106.6568 | N8: 8890 | O8: =+O7*(1+(N8/N7-1)) -> 113.82843
A9: 2024/12/19 | B9: 53100 | C9: =+C8*(1+(B9/B8-1)) -> 98.333333 | D9: 175000 | E9: =+E8*(1+(D9/D8-1)) -> 102.69953 | F9: 16480 | G9: =+G8*(1+(F9/F8-1)) -> 104.83461 | H9: 13040 | I9: =+I8*(1+(H9/H8-1)) -> 101.63679 | J9: 23200 | K9: =+K8*(1+(J9/J8-1)) -> 102.20264 | L9: 69900 | M9: =+M8*(1+(L9/L8-1)) -> 103.40237 | N9: 8600 | O9: =+O8*(1+(N9/N8-1)) -> 110.11524
A10: 2024/12/20 | B10: 53000 | C10: =+C9*(1+(B10/B9-1)) -> 98.148148 | D10: 168500 | E10: =+E9*(1+(D10/D9-1)) -> 98.884977 | F10: 16080 | G10: =+G9*(1+(F10/F9-1)) -> 102.29008 | H10: 12430 | I10: =+I9*(1+(H10/H9-1)) -> 96.882307 | J10: 23050 | K10: =+K9*(1+(J10/J9-1)) -> 101.54185 | L10: 68000 | M10: =+M9*(1+(L10/L9-1)) -> 100.59172 | N10: 8270 | O10: =+O9*(1+(N10/N9-1)) -> 105.88988
A11: 2024/12/23 | B11: 53500 | C11: =+C10*(1+(B11/B10-1)) -> 99.074074 | D11: 169600 | E11: =+E10*(1+(D11/D10-1)) -> 99.530516 | F11: 16540 | G11: =+G10*(1+(F11/F10-1)) -> 105.21628 | H11: 12990 | I11: =+I10*(1+(H11/H10-1)) -> 101.24708 | J11: 23850 | K11: =+K10*(1+(J11/J10-1)) -> 105.06608 | L11: 69700 | M11: =+M10*(1+(L11/L10-1)) -> 103.10651 | N11: 8460 | O11: =+O10*(1+(N11/N10-1)) -> 108.32266
A12: 2024/12/24 | B12: 54400 | C12: =+C11*(1+(B12/B11-1)) -> 100.74074 | D12: 168500 | E12: =+E11*(1+(D12/D11-1)) -> 98.884977 | F12: 16530 | G12: =+G11*(1+(F12/F11-1)) -> 105.15267 | H12: 12670 | I12: =+I11*(1+(H12/H11-1)) -> 98.752923 | J12: 24150 | K12: =+K11*(1+(J12/J11-1)) -> 106.38767 | L12: 69700 | M12: =+M11*(1+(L12/L11-1)) -> 103.10651 | N12: 8220 | O12: =+O11*(1+(N12/N11-1)) -> 105.24968
A13: 2024/12/26 | B13: 53600 | C13: =+C12*(1+(B13/B12-1)) -> 99.259259 | D13: 170100 | E13: =+E12*(1+(D13/D12-1)) -> 99.823944 | F13: 16450 | G13: =+G12*(1+(F13/F12-1)) -> 104.64377 | H13: 12290 | I13: =+I12*(1+(H13/H12-1)) -> 95.791115 | J13: 23500 | K13: =+K12*(1+(J13/J12-1)) -> 103.52423 | L13: 70000 | M13: =+M12*(1+(L13/L12-1)) -> 103.5503 | N13: 8020 | O13: =+O12*(1+(N13/N12-1)) -> 102.68886
A14: 2024/12/27 | B14: 53700 | C14: =+C13*(1+(B14/B13-1)) -> 99.444444 | D14: 174500 | E14: =+E13*(1+(D14/D13-1)) -> 102.4061 | F14: 16500 | G14: =+G13*(1+(F14/F13-1)) -> 104.96183 | H14: 14050 | I14: =+I13*(1+(H14/H13-1)) -> 109.50896 | J14: 22750 | K14: =+K13*(1+(J14/J13-1)) -> 100.22026 | L14: 70100 | M14: =+M13*(1+(L14/L13-1)) -> 103.69822 | N14: 8000 | O14: =+O13*(1+(N14/N13-1)) -> 102.43278
... A244: 2025/12/10 | B244: 108000 | C244: =+C243*(1+(B244/B243-1)) -> 200 | D244: 587000 | E244: =+E243*(1+(D244/D243-1)) -> 344.48357 | F244: 22450 | G244: =+G243*(1+(F244/F243-1)) -> 142.8117 | H244: 23850 | I244: =+I243*(1+(H244/H243-1)) -> 185.89244 | J244: 43650 | K244: =+K243*(1+(J244/J243-1)) -> 192.29075 | L244: 147100 | M244: =+M243*(1+(L244/L243-1)) -> 217.60355 | N244: 13650 | O244: =+O243*(1+(N244/N243-1)) -> 174.77593
A245: 2025/12/11
A246: 2025/12/12

Sheet Sheet1
A1: 45981 | B1: 131600 | C1: 100
A2: 45982 | B2: 103800 | C2: =+C1*(1+B2/B1-1) -> 78.87538
A3: 45985 | B3: 98300 | C3: =+C2*(1+B3/B2-1) -> 74.696049
A4: 45986 | B4: 92100 | C4: =+C3*(1+B4/B3-1) -> 69.984802
A5: 45987 | B5: 92300 | C5: =+C4*(1+B5/B4-1) -> 70.136778
A6: 45988 | B6: 95400 | C6: =+C5*(1+B6/B5-1) -> 72.492401
A7: 45989 | B7: 91200 | C7: =+C6*(1+B7/B6-1) -> 69.300912
A8: 45992 | B8: 94100 | C8: =+C7*(1+B8/B7-1) -> 71.504559
A9: 45993 | B9: 91900 | C9: =+C8*(1+B9/B8-1) -> 69.832827
A10: 45994 | B10: 87600 | C10: =+C9*(1+B10/B9-1) -> 66.56535
A11: 45995 | B11: 88600 | C11: =+C10*(1+B11/B10-1) -> 67.325228
A12: 45996 | B12: 83500 | C12: =+C11*(1+B12/B11-1) -> 63.449848
A13: 45999 | B13: 84200 | C13: =+C12*(1+B13/B12-1) -> 63.981763
... A17: 46003 | B17: 75900 | C17: =+C16*(1+B17/B16-1) -> 57.674772
